Workbook

Sheet 總表
A1: 臺中管理處地下水水權狀總表
A2: 編號 | B2: 站別 | C2: 名稱 | D2: 水權狀號 | E2: 核准 | F2: 年限 | G2: 灌溉面積(ha) | H2: 引水地點 | I2: 使用方法 | J2: 引用水量(cms) | K2: 每日用水時間(hr) | L2: 年可引用水量(m³) | M2: 水井深度(m) | N2: 引水月份 | O2: 水系 | S2: cmd
A3: =SUBTOTAL(103,$B$3:B3) -> 1 | B3: 卓蘭 | C3: 苗豐抽水井 | D3: K0124239 | E3: 1120808 | F3: 1170807 | G3: 7.108158 | H3: 苗栗縣卓蘭鎮苗豐段277地號 | J3: 0.0169 | K3: 16 | L3: =J3*K3*60*60*365 -> 355305.6 | M3: 120 | N3: 每月 | O3: 大安溪 | S3: =J3*K3*60*60 -> 973.44
A4: =SUBTOTAL(103,$B$3:B4) -> 2 | B4: 山腳 | C4: 泰田抽水井 | D4: K0086033 | E4: 1110401 | F4: 1160331 | G4: 5.1547 | H4: 苗栗縣苑裡鎮泰田段647-1地號 | J4: 0.0136 | K4: 20 | L4: =J4*K4*60*60*365 -> 357408 | M4: 120 | N4: 每月 | O4: 大安溪 | S4: =J4*K4*60*60 -> 979.2
A5: =SUBTOTAL(103,$B$3:B5) -> 3 | B5: 山腳 | C5: 社柑抽水井 | D5: K0086034 | E5: 1110401 | F5: 1160331 | G5: 13.81053 | H5: 苗栗縣苑裡鎮社柑段1220-1地號 | J5: 0.042 | K5: 20 | L5: =J5*K5*60*60*365 -> 1103760 | M5: 120 | N5: 每月 | O5: 大安溪 | S5: =J5*K5*60*60 -> 3024
A6: =SUBTOTAL(103,$B$3:B6) -> 4 | B6: 山腳 | C6: 社南抽水井 | D6: K0123393 | E6: 1111101 | F6: 1161031 | G6: 8.877913 | H6: 苗栗縣苑裡鎮鎮安段23-1地號 | J6: 0.016 | K6: 20 | L6: =J6*K6*60*60*365 -> 420480 | M6: 75 | N6: 每月 | O6: 大安溪 | S6: =J6*K6*60*60 -> 1152
A7: =SUBTOTAL(103,$B$3:B7) -> 5 | B7: 山腳 | C7: 濁一抽水井 | D7: K0123725 | E7: 1110101 | F7: 1151231 | G7: 9.203787 | H7: 苗栗縣苑裡鎮啟心段1248-1地號 | J7: 0.038 | K7: 20 | L7: =J7*K7*60*60*365 -> 998640 | M7: 156 | N7: 每月 | O7: 大安溪 | S7: =J7*K7*60*60 -> 2736
A8: =SUBTOTAL(103,$B$3:B8) -> 6 | B8: 山腳 | C8: 啟心抽水井 | D8: K0123768 | E8: 1121201 | F8: 1171130 | G8: 13.0317 | H8: 苗栗縣苑裡鎮啟心段728地號 | J8: 0.03 | K8: 20 | L8: =J8*K8*60*60*365 -> 788400 | M8: 180 | N8: 每月 | O8: 大安溪 | S8: =J8*K8*60*60 -> 2160
A9: =SUBTOTAL(103,$B$3:B9) -> 7 | B9: 山腳 | C9: 山柑一號抽水井 | D9: K1140087 | E9: 1140811 | F9: 1190810 | G9: 9.616475 | H9: 苗栗縣苑裡鎮火炎山段401地號 | J9: 0.035 | K9: 20 | L9: =J9*K9*60*60*365 -> 919800 | M9: 100 | N9: 每月 | O9: 大安溪 | P9: 114年8月重新許可 | S9: =J9*K9*60*60 -> 2520
A10: =SUBTOTAL(103,$B$3:B10) -> 8 | B10: 山腳 | C10: 山柑二號抽水井 | D10: K0124362 | E10: 1130711 | F10: 1180710 | G10: 9.796735 | H10: 苗栗縣苑裡鎮社柑段2201-1地號 | J10: 0.035 | K10: 20 | L10: =J10*K10*60*60*365 -> 919800 | M10: 42 | N10: 每月 | O10: 大安溪 | S10: =J10*K10*60*60 -> 2520
A11: =SUBTOTAL(103,$B$3:B11) -> 9 | B11: 山腳 | C11: 濁水二號抽水井 | D11: K1140122 | E11: 1141011 | F11: 1191010 | G11: 6.279985 | H11: 苗栗縣苑裡鎮火炎山段974-1地號 | J11: 0.023 | K11: 20 | L11: =J11*K11*60*60*365 -> 604440 | M11: 100 | N11: 每月 | O11: 大安溪 | P11: 114年10月新增 | S11: =J11*K11*60*60 -> 1656
A12: =SUBTOTAL(103,$B$3:B12) -> 10 | B12: 苑裡 | C12: 新復一號抽水井 | D12: K0123688 | E12: 1110101 | F12: 1151231 | G12: 20.77669 | H12: 苗栗縣苑裡鎮新復東段702地號 | J12: 0.0613 | K12: 20 | L12: =J12*K12*60*60*365 -> 1610964 | M12: 150 | N12: 每月 | O12: 大安溪 | S12: =J12*K12*60*60 -> 4413.6
A13: =SUBTOTAL(103,$B$3:B13) -> 11 | B13: 苑裡 | C13: 新復二號抽水井 | D13: K0123786 | E13: 1130201 | F13: 1180131 | G13: 9.373183 | H13: 苗栗縣苑裡鎮新復東段277-1地號 | J13: 0.038 | K13: 20 | L13: =J13*K13*60*60*365 -> 998640 | M13: 96 | N13: 每月 | O13: 大安溪 | S13: =J13*K13*60*60 -> 2736
A14: =SUBTOTAL(103,$B$3:B14) -> 12 | B14: 苑裡 | C14: 田心小組抽水井 | D14: K0123766 | E14: 1121201 | F14: 1171130 | G14: 17.7692 | H14: 苗栗縣苑裡鎮田中段620地號 | J14: 0.07 | K14: 20 | L14: =J14*K14*60*60*365 -> 1839600 | M14: 84 | N14: 每月 | O14: 大安溪 | S14: =J14*K14*60*60 -> 5040
A15: =SUBTOTAL(103,$B$3:B15) -> 13 | B15: 苑裡 | C15: 田心二號抽水井 | D15: K0124420 | E15: 1140401 | F15: 1190331 | G15: 12.9296 | H15: 苗栗縣苑裡鎮田中段1068地號 | J15: 0.0525 | K15: 20 | L15: =J15*K15*60*60*365 -> 1379700 | M15: 126 | N15: 每月 | O15: 大安溪 | S15: =J15*K15*60*60 -> 3780
A16: =SUBTOTAL(103,$B$3:B16) -> 14 | B16: 苑裡 | C16: 西勢支線抽水井 | D16: K0123779 | E16: 1130201 | F16: 1180131 | G16: 4.3805 | H16: 苗栗縣苑裡鎮西海段452地號 | J16: 0.0175 | K16: 20 | L16: =J16*K16*60*60*365 -> 459900 | M16: 150 | N16: 每月 | O16: 大安溪 | S16: =J16*K16*60*60 -> 1260
A17: =SUBTOTAL(103,$B$3:B17) -> 15 | B17: 苑裡 | C17: 砂埤支線抽水井 | D17: K0124485 | E17: 1140901 | F17: 1190831 | G17: 6.1158 | H17: 苗栗縣苑裡鎮舊社段644-5地號 | J17: 0.025 | K17: 20 | L17: =J17*K17*60*60*365 -> 657000 | M17: 84 | N17: 每月 | O17: 大安溪 | S17: =J17*K17*60*60 -> 1800
A18: =SUBTOTAL(103,$B$3:B18) -> 16 | B18: 泰安 | C18: 新店圳一號抽水井 | D18: B0130278 | E18: 1120201 | F18: 1170131 | G18: 23.758244 | H18: 臺中市后里區新店東段42地號 | J18: 0.076 | K18: 20 | L18: =J18*K18*60*60*365 -> 1997280 | M18: 120 | N18: 每月 | O18: 大安溪 | S18: =J18*K18*60*60 -> 5472
A19: =SUBTOTAL(103,$B$3:B19) -> 17 | B19: 泰安 | C19: 七公圳一號抽水井 | D19: B0130267 | E19: 1120201 | F19: 1170131 | G19: 23.946354 | H19: 臺中市后里區泰安段348地號 | J19: 0.076 | K19: 20 | L19: =J19*K19*60*60*365 -> 1997280 | M19: 120 | N19: 每月 | O19: 大安溪 | S19: =J19*K19*60*60 -> 5472
A20: =SUBTOTAL(103,$B$3:B20) -> 18 | B20: 泰安 | C20: 七公圳二號抽水井 | D20: B1040342 | E20: 1140624 | F20: 1190623 | G20: 4.6187 | H20: 臺中市后里區里城段1地號東側 | J20: 0.0482 | K20: 8.15 | L20: =J20*K20*60*60*365 -> 516178.62 | M20: 120 | N20: 每月 | O20: 大安溪 | P20: 1140624，引水月份由2-4月修正為全年 | S20: =J20*K20*60*60 -> 1414.188
A21: =SUBTOTAL(103,$B$3:B21) -> 19 | B21: 泰安 | C21: 新店圳二號抽水井 | D21: B1140020 | E21: 1140108 | F21: 1190107 | G21: 2.041091 | H21: 臺中市后里區新店西段531-1地號 | J21: 0.032 | K21: 4.6 | L21: =J21*K21*60*60*365 -> 193420.8 | M21: 80 | N21: 每月 | O21: 大安溪 | P21: 114年1月新增 | S21: =J21*K21*60*60 -> 529.92
A22: =SUBTOTAL(103,$B$3:B22) -> 20 | B22: 泰安 | C22: 新店圳三號抽水井 | D22: B1140033 | E22: 1140120 | F22: 1190119 | G22: 2.335306 | H22: 臺中市外埔區上土城段37-1地號 | J22: 0.028 | K22: 6.5 | L22: =(((J22*K22)*60)*60)*365 -> 239148 | M22: 80 | N22: 每月 | O22: 大安溪 | P22: 114年1月新增 | S22: =J22*K22*60*60 -> 655.2
A23: =SUBTOTAL(103,$B$3:B23) -> 21 | B23: 屯子腳 | C23: 內埔圳一號抽水井 | D23: B0970028 | E23: 1120801 | F23: 1170731 | G23: 7.725775 | H23: 臺中市后里區七星段50地號 | J23: 0.075 | K23: 7 | L23: =J23*K23*60*60*365 -> 689850 | M23: 150 | N23: 每月 | O23: 大甲溪 | S23: =J23*K23*60*60 -> 1890
A24: =SUBTOTAL(103,$B$3:B24) -> 22 | B24: 屯子腳 | C24: 內埔圳二號抽水井 | D24: B0970027 | E24: 1120801 | F24: 1170731 | G24: 6.240027 | H24: 臺中市后里區平安段1221地號 | J24: 0.035 | K24: 10 | L24: =J24*K24*60*60*365 -> 459900 | M24: 120 | N24: 每月 | O24: 大甲溪 | S24: =J24*K24*60*60 -> 1260
A25: =SUBTOTAL(103,$B$3:B25) -> 23 | B25: 屯子腳 | C25: 內埔圳二支線一號抽水井 | D25: B1070014 | E25: 1120125 | F25: 1170124 | G25: 5.8769 | H25: 臺中市后里區金社庄段324地號 | J25: 0.0286 | K25: 7 | L25: =J25*K25*60*60*365 -> 263062.8 | M25: 150 | N25: 每月 | O25: 大甲溪 | S25: =J25*K25*60*60 -> 720.72
A26: =SUBTOTAL(103,$B$3:B26) -> 24 | B26: 屯子腳 | C26: 內埔圳二支線二號抽水井 | D26: B1100760 | E26: 1101115 | F26: 1151114 | G26: 5.4643 | H26: 臺中市后里區金城段516-2地號 | J26: 0.039 | K26: 12 | L26: =J26*K26*60*60*365 -> 614952 | M26: 138 | N26: 每月 | O26: 大甲溪 | S26: =J26*K26*60*60 -> 1684.8
A27: =SUBTOTAL(103,$B$3:B27) -> 25 | B27: 屯子腳 | C27: 內埔圳梅仔腳溝支線水井 | D27: B1140111 | E27: 1140513 | F27: 1190512 | G27: 3.432504 | H27: 臺中市后里區枋寮段1014-0000號 | J27: 0.07 | K27: 4 | L27: =J27*K27*60*60*365 -> 367920 | M27: 100 | N27: 每月 | O27: 大甲溪 | P27: 1140512新增 | S27: =J27*K27*60*60 -> 1008
A28: =SUBTOTAL(103,$B$3:B28) -> 26 | B28: 磁瑤 | C28: 后里圳一號抽水井 | D28: B0112603 | E28: 1131031 | F28: 1181030 | G28: 9.0875 | H28: 臺中市外埔區頂竹圍段104地號 | J28: 0.023 | K28: 20 | L28: =J28*K28*60*60*365 -> 604440 | M28: 150 | N28: 每月 | O28: 大安溪 | S28: =J28*K28*60*60 -> 1656
A29: =SUBTOTAL(103,$B$3:B29) -> 27 | B29: 磁瑤 | C29: 后里圳三號抽水井 | D29: B0930053 | E29: 1131216 | F29: 1181215 | G29: 2.2667 | H29: 臺中市外埔區下鐵山段862地號 | J29: 0.016 | K29: 12 | L29: =J29*K29*60*60*365 -> 252288 | M29: 180 | N29: 每月 | O29: 大安溪 | S29: =J29*K29*60*60 -> 691.2
A30: =SUBTOTAL(103,$B$3:B30) -> 28 | B30: 磁瑤 | C30: 后里圳四號抽水井 | D30: B0950059 | E30: 1100901 | F30: 1150831 | G30: 0.4965 | H30: 臺中市外埔區上鐵山段137地號 | J30: 0.0053 | K30: 8 | L30: =J30*K30*60*60*365 -> 55713.6 | M30: 121 | N30: 每月 | O30: 大安溪 | S30: =J30*K30*60*60 -> 152.64
A31: =SUBTOTAL(103,$B$3:B31) -> 29 | B31: 磁瑤 | C31: 后里圳七支線二號抽水井 | D31: B1070109 | E31: 1120622 | F31: 1170621 | G31: 1.910968 | H31: 臺中市外埔區永吉段1182地號 | J31: 0.016 | K31: 8.5 | L31: =J31*K31*60*60*365 -> 178704 | M31: 150 | N31: 每月 | O31: 大安溪 | S31: =J31*K31*60*60 -> 489.6
A32: =SUBTOTAL(103,$B$3:B32) -> 30 | B32: 磁瑤 | C32: 后里圳六支線一號抽水井 | D32: B1080127 | E32: 1130721 | F32: 1180720 | G32: 4.1153 | H32: 臺中市外埔區三崁段366地號 | J32: 0.028 | K32: 10.5 | L32: =J32*K32*60*60*365 -> 386316 | M32: 150 | N32: 每月 | O32: 大安溪 | S32: =J32*K32*60*60 -> 1058.4
A33: =SUBTOTAL(103,$B$3:B33) -> 31 | B33: 磁瑤 | C33: 后里圳七支線一號抽水井 | D33: B1100779 | E33: 1101201 | F33: 1151130 | G33: 2.187488 | H33: 臺中市外埔區新六分段564地號 | J33: 0.008 | K33: 20 | L33: =J33*K33*60*60*365 -> 210240 | M33: 150 | N33: 每月 | O33: 大安溪 | S33: =J33*K33*60*60 -> 576
A34: =SUBTOTAL(103,$B$3:B34) -> 32 | B34: 磁瑤 | C34: 后里圳二號抽水井 | D34: B1140109 | E34: 1140513 | F34: 1190512 | G34: 1.785797 | H34: 臺中市外埔區頂竹圍段0105-0000地號 | J34: 0.0116 | K34: 0.5 | L34: =J34*K34*60*60*365 -> 7621.2 | M34: 150 | N34: 每月 | O34: 大安溪 | P34: 1140515新增 | S34: =J34*K34*60*60 -> 20.88
A35: =SUBTOTAL(103,$B$3:B35) -> 33 | B35: 磁瑤 | C35: 后里圳七支線三號抽水井 | D35: B1140110 | E35: 1140513 | F35: 1190512 | G35: 0.835569 | H35: 臺中市外埔區新磁瑤段0138-0000地號 | J35: 0.0162 | K35: 1.5 | L35: =J35*K35*60*60*365 -> 31930.2 | M35: 130 | N35: 每月 | O35: 大安溪 | P35: 1140515新增 | S35: =J35*K35*60*60 -> 87.48 | U35: =SUM(J36:J52) -> 0.4957
A36: =SUBTOTAL(103,$B$3:B36) -> 34 | B36: 月眉 | C36: 后里圳幹線抽水井 | D36: B1090023 | E36: 1140301 | F36: 1190228 | G36: 3.121956 | H36: 臺中市后里區四月段264地號 | J36: 0.033 | K36: 7 | L36: =J36*K36*60*60*365 -> 303534 | M36: 150 | N36: 每月 | O36: 大安溪 | S36: =J36*K36*60*60 -> 831.6 | U36: =SUM(J28:J35) -> 0.1241
A37: =SUBTOTAL(103,$B$3:B37) -> 35 | B37: 月眉 | C37: 月眉站舊辦公廳地下水抽水井 | D37: B0130304 | E37: 1120301 | F37: 1170229 | G37: 0.5 | H37: 臺中市后里區后寶段792地號 | J37: 0.009 | K37: 10 | L37: =J37*K37*60*60*365 -> 118260 | M37: 91 | N37: 每月 | O37: 大安溪 | S37: =J37*K37*60*60 -> 324
A38: =SUBTOTAL(103,$B$3:B38) -> 36 | B38: 月眉 | C38: 后里圳月眉排水補給抽水井 | D38: B1070176 | E38: 1120921 | F38: 1170920 | G38: 4.7724 | H38: 臺中市后里區四塊厝段350地號 | J38: 0.034 | K38: 6.5 | L38: =J38*K38*60*60*365 -> 290394 | M38: 150 | N38: 每月 | O38: 大安溪 | S38: =J38*K38*60*60 -> 795.6
A39: =SUBTOTAL(103,$B$3:B39) -> 37 | B39: 月眉 | C39: 后里圳三支線上游補給抽水井 | D39: B1060117 | E39: 1111023 | F39: 1161022 | G39: 5.060208 | H39: 臺中市后里區眉山西段279地號 | J39: 0.036 | K39: 12 | L39: =J39*K39*60*60*365 -> 567648 | M39: 150 | N39: 每月 | O39: 大安溪 | S39: =J39*K39*60*60 -> 1555.2
A40: =SUBTOTAL(103,$B$3:B40) -> 38 | B40: 月眉 | C40: 后里圳三支線中游補給抽水井 | D40: B1040345 | E40: 1140702 | F40: 1190701 | G40: 8.365843 | H40: 臺中市后里區四塊庄段401地號 | J40: 0.033 | K40: 16 | L40: =J40*K40*60*60*365 -> 693792 | M40: 150 | N40: 每月 | O40: 大安溪 | S40: =J40*K40*60*60 -> 1900.8
...

Sheet 月實取水量表
A2: 編號 | B2: 站別 | C2: 名稱 | D2: 水權狀號 | E2: 一月 | F2: 二月 | G2: 三月 | H2: 四月 | I2: 五月 | J2: 六月 | K2: 七月 | L2: 八月 | M2: 九月 | N2: 十月 | O2: 十一月 | P2: 十二月 | Q2: 年實取水量(m³)
A3: 1 | B3: ='總表'!B3 -> 卓蘭 | C3: ='總表'!C3 -> 苗豐抽水井 | D3: ='總表'!D3 -> K0124239 | E3: ='卓蘭站'!$D8 -> 26.34372 | F3: ='卓蘭站'!$D9 -> 801.2628 | G3: ='卓蘭站'!$D10 -> 2255.9472 | H3: ='卓蘭站'!$D11 -> 10.139996 | I3: ='卓蘭站'!$D12 -> 0 | J3: ='卓蘭站'!$D13 -> 1679.184 | K3: ='卓蘭站'!$D14 -> 906.51539 | L3: ='卓蘭站'!$D15 | M3: ='卓蘭站'!$D16 | N3: ='卓蘭站'!$D17 | O3: ='卓蘭站'!$D18 | P3: ='卓蘭站'!$D19 | Q3: =SUM(E3:P3) -> 5679.3931
A4: 2 | B4: ='總表'!B4 -> 山腳 | C4: ='總表'!C4 -> 泰田抽水井 | D4: ='總表'!D4 -> K0086033 | E4: ='山腳站'!$D8 -> 0 | F4: ='山腳站'!$D9 -> 0 | G4: ='山腳站'!$D10 -> 0 | H4: ='山腳站'!$D11 -> 0 | I4: ='山腳站'!$D12 -> 0 | J4: ='山腳站'!$D13 -> 0 | K4: ='山腳站'!$D14 -> 0 | L4: ='山腳站'!$D15 | M4: ='山腳站'!$D16 | N4: ='山腳站'!$D17 | O4: ='山腳站'!$D18 | P4: ='山腳站'!$D19 | Q4: =SUM(E4:P4) -> 0
A5: 3 | B5: ='總表'!B5 -> 山腳 | C5: ='總表'!C5 -> 社柑抽水井 | D5: ='總表'!D5 -> K0086034 | E5: ='山腳站'!$H8 -> 302.4 | F5: ='山腳站'!$H9 -> 21772.8 | G5: ='山腳站'!$H10 -> 38556 | H5: ='山腳站'!$H11 -> 16632 | I5: ='山腳站'!$H12 -> 18144 | J5: ='山腳站'!$H13 -> 15120 | K5: ='山腳站'!$H14 -> 15120 | L5: ='山腳站'!$H15 | M5: ='山腳站'!$H16 | N5: ='山腳站'!$H17 | O5: ='山腳站'!$H18 | P5: ='山腳站'!$H19 | Q5: =SUM(E5:P5) -> 125647.2
A6: 4 | B6: ='總表'!B6 -> 山腳 | C6: ='總表'!C6 -> 社南抽水井 | D6: ='總表'!D6 -> K0123393 | E6: ='山腳站'!$L8 -> 115.2 | F6: ='山腳站'!$L9 -> 8294.4 | G6: ='山腳站'!$L10 -> 14688 | H6: ='山腳站'!$L11 -> 8064 | I6: ='山腳站'!$L12 -> 8064 | J6: ='山腳站'!$L13 -> 6336 | K6: ='山腳站'!$L14 -> 6336 | L6: ='山腳站'!$L15 | M6: ='山腳站'!$L16 | N6: ='山腳站'!$L17 | O6: ='山腳站'!$L18 | P6: ='山腳站'!$L19 | Q6: =SUM(E6:P6) -> 51897.6
A7: 5 | B7: ='總表'!B7 -> 山腳 | C7: ='總表'!C7 -> 濁一抽水井 | D7: ='總表'!D7 -> K0123725 | E7: ='山腳站'!$P8 -> 273.6 | F7: ='山腳站'!$P9 -> 19699.2 | G7: ='山腳站'!$P10 -> 19836 | H7: ='山腳站'!$P11 -> 6566.4 | I7: ='山腳站'!$P12 -> 1094.4 | J7: ='山腳站'!$P13 -> 1094.4 | K7: ='山腳站'!$P14 -> 1094.4 | L7: ='山腳站'!$P15 | M7: ='山腳站'!$P16 | N7: ='山腳站'!$P17 | O7: ='山腳站'!$P18 | P7: ='山腳站'!$P19 | Q7: =SUM(E7:P7) -> 49658.4
A8: 6 | B8: ='總表'!B8 -> 山腳 | C8: ='總表'!C8 -> 啟心抽水井 | D8: ='總表'!D8 -> K0123768 | E8: ='山腳站'!$T8 -> 216 | F8: ='山腳站'!$T9 -> 13608 | G8: ='山腳站'!$T10 -> 11232 | H8: ='山腳站'!$T11 -> 5184 | I8: ='山腳站'!$T12 -> 0 | J8: ='山腳站'!$T13 -> 0 | K8: ='山腳站'!$T14 -> 0 | L8: ='山腳站'!$T15 | M8: ='山腳站'!$T16 | N8: ='山腳站'!$T17 | O8: ='山腳站'!$T18 | P8: ='山腳站'!$T19 | Q8: =SUM(E8:P8) -> 30240
A9: 7 | B9: ='總表'!B9 -> 山腳 | C9: ='總表'!C9 -> 山柑一號抽水井 | D9: ='總表'!D9 -> K1140087 | E9: ='山腳站'!$X8 -> 0 | F9: ='山腳站'!$X9 -> 0 | G9: ='山腳站'!$X10 -> 0 | H9: ='山腳站'!$X11 -> 126 | I9: ='山腳站'!$X12 -> 630 | J9: ='山腳站'!$X13 -> 1008 | K9: ='山腳站'!$X14 -> 1008 | L9: ='山腳站'!$X15 | M9: ='山腳站'!$X16 | N9: ='山腳站'!$X17 | O9: ='山腳站'!$X18 | P9: ='山腳站'!$X19 | Q9: =SUM(E9:P9) -> 2772 | R9: 原井報廢，舊址鑿新井，會有新的水權號
A10: 8 | B10: ='總表'!B10 -> 山腳 | C10: ='總表'!C10 -> 山柑二號抽水井 | D10: ='總表'!D10 -> K0124362 | E10: ='山腳站'!$AB8 -> 252 | F10: ='山腳站'!$AB9 -> 18144 | G10: ='山腳站'!$AB10 -> 20160 | H10: ='山腳站'!$AB11 -> 2016 | I10: ='山腳站'!$AB12 -> 2646 | J10: ='山腳站'!$AB13 -> 3024 | K10: ='山腳站'!$AB14 -> 15120 | L10: ='山腳站'!$AB15 | M10: ='山腳站'!$AB16 | N10: ='山腳站'!$AB17 | O10: ='山腳站'!$AB18 | P10: ='山腳站'!$AB19 | Q10: =SUM(E10:P10) -> 61362
A11: 9 | B11: ='總表'!B11 -> 山腳 | C11: ='總表'!C11 -> 濁水二號抽水井 | D11: ='總表'!D11 -> K1140122 | E11: ='山腳站'!$AF8 -> 0 | F11: ='山腳站'!$AF9 -> 0 | G11: ='山腳站'!$AF10 -> 0 | H11: ='山腳站'!$AF11 -> 0 | I11: ='山腳站'!$AF12 -> 0 | J11: ='山腳站'!$AF13 -> 331.2 | K11: ='山腳站'!$AF14 -> 579.6 | L11: ='山腳站'!$AF15 | M11: ='山腳站'!$AF16 | N11: ='山腳站'!$AF17 | O11: ='山腳站'!$AF18 | P11: ='山腳站'!$AF19 | Q11: =SUM(E11:P11) -> 910.8
A12: 10 | B12: ='總表'!B12 -> 苑裡 | C12: ='總表'!C12 -> 新復一號抽水井 | D12: ='總表'!D12 -> K0123688 | E12: ='苑裡站'!$D8 -> 0 | F12: ='苑裡站'!$D9 -> 52963.2 | G12: ='苑裡站'!$D10 -> 68852.16 | H12: ='苑裡站'!$D11 -> 32881.32 | I12: ='苑裡站'!$D12 -> 41487.84 | J12: ='苑裡站'!$D13 -> 36853.56 | K12: ='苑裡站'!$D14 -> 0 | L12: ='苑裡站'!$D15 | M12: ='苑裡站'!$D16 | N12: ='苑裡站'!$D17 | O12: ='苑裡站'!$D18 | P12: ='苑裡站'!$D19 | Q12: =SUM(E12:P12) -> 233038.08
A13: 11 | B13: ='總表'!B13 -> 苑裡 | C13: ='總表'!C13 -> 新復二號抽水井 | D13: ='總表'!D13 -> K0123786 | E13: ='苑裡站'!$H8 -> 0 | F13: ='苑裡站'!$H9 -> 32832 | G13: ='苑裡站'!$H10 -> 42681.6 | H13: ='苑裡站'!$H11 -> 26265.6 | I13: ='苑裡站'!$H12 -> 31600.8 | J13: ='苑裡站'!$H13 -> 22845.6 | K13: ='苑裡站'!$H14 -> 0 | L13: ='苑裡站'!$H15 | M13: ='苑裡站'!$H16 | N13: ='苑裡站'!$H17 | O13: ='苑裡站'!$H18 | P13: ='苑裡站'!$H19 | Q13: =SUM(E13:P13) -> 156225.6
A14: 12 | B14: ='總表'!B14 -> 苑裡 | C14: ='總表'!C14 -> 田心小組抽水井 | D14: ='總表'!D14 -> K0123766 | E14: ='苑裡站'!$L8 -> 0 | F14: ='苑裡站'!$L9 -> 51408 | G14: ='苑裡站'!$L10 -> 109368 | H14: ='苑裡站'!$L11 -> 37548 | I14: ='苑裡站'!$L12 -> 27720 | J14: ='苑裡站'!$L13 -> 42084 | K14: ='苑裡站'!$L14 -> 0 | L14: ='苑裡站'!$L15 | M14: ='苑裡站'!$L16 | N14: ='苑裡站'!$L17 | O14: ='苑裡站'!$L18 | P14: ='苑裡站'!$L19 | Q14: =SUM(E14:P14) -> 268128
A15: 13 | B15: ='總表'!B15 -> 苑裡 | C15: ='總表'!C15 -> 田心二號抽水井 | D15: ='總表'!D15 -> K0124420 | E15: ='苑裡站'!$P8 -> 0 | F15: ='苑裡站'!$P9 -> 37233 | G15: ='苑裡站'!$P10 -> 82026 | H15: ='苑裡站'!$P11 -> 28161 | I15: ='苑裡站'!$P12 -> 33264 | J15: ='苑裡站'!$P13 -> 31563 | K15: ='苑裡站'!$P14 -> 0 | L15: ='苑裡站'!$P15 | M15: ='苑裡站'!$P16 | N15: ='苑裡站'!$P17 | O15: ='苑裡站'!$P18 | P15: ='苑裡站'!$P19 | Q15: =SUM(E15:P15) -> 212247
A16: 14 | B16: ='總表'!B16 -> 苑裡 | C16: ='總表'!C16 -> 西勢支線抽水井 | D16: ='總表'!D16 -> K0123779 | E16: ='苑裡站'!$T8 -> 0 | F16: ='苑裡站'!$T9 -> 4536 | G16: ='苑裡站'!$T10 -> 18522 | H16: ='苑裡站'!$T11 -> 4725 | I16: ='苑裡站'!$T12 -> 5796 | J16: ='苑裡站'!$T13 -> 3024 | K16: ='苑裡站'!$T14 -> 0 | L16: ='苑裡站'!$T15 | M16: ='苑裡站'!$T16 | N16: ='苑裡站'!$T17 | O16: ='苑裡站'!$T18 | P16: ='苑裡站'!$T19 | Q16: =SUM(E16:P16) -> 36603
A17: 15 | B17: ='總表'!B17 -> 苑裡 | C17: ='總表'!C17 -> 砂埤支線抽水井 | D17: ='總表'!D17 -> K0124485 | E17: ='苑裡站'!$X8 -> 0 | F17: ='苑裡站'!$X9 -> 19440 | G17: ='苑裡站'!$X10 -> 35820 | H17: ='苑裡站'!$X11 -> 17280 | I17: ='苑裡站'!$X12 -> 9900 | J17: ='苑裡站'!$X13 -> 15030 | K17: ='苑裡站'!$X14 -> 0 | L17: ='苑裡站'!$X15 | M17: ='苑裡站'!$X16 | N17: ='苑裡站'!$X17 | O17: ='苑裡站'!$X18 | P17: ='苑裡站'!$X19 | Q17: =SUM(E17:P17) -> 97470
A18: 16 | B18: ='總表'!B18 -> 泰安 | C18: ='總表'!C18 -> 新店圳一號抽水井 | D18: ='總表'!D18 -> B0130278 | E18: ='泰安站'!$D8 -> 1915.2 | F18: ='泰安站'!$D9 -> 20793.6 | G18: ='泰安站'!$D10 -> 203558.4 | H18: ='泰安站'!$D11 -> 72504 | I18: ='泰安站'!$D12 -> 113270.4 | J18: ='泰安站'!$D13 -> 3830.4 | K18: ='泰安站'!$D14 -> 0 | L18: ='泰安站'!$D15 | M18: ='泰安站'!$D16 | N18: ='泰安站'!$D17 | O18: ='泰安站'!$D18 | P18: ='泰安站'!$D19 | Q18: =SUM(E18:P18) -> 415872
A19: 17 | B19: ='總表'!B19 -> 泰安 | C19: ='總表'!C19 -> 七公圳一號抽水井 | D19: ='總表'!D19 -> B0130267 | E19: ='泰安站'!$H8 -> 7934.4 | F19: ='泰安站'!$H9 -> 63475.2 | G19: ='泰安站'!$H10 -> 140904 | H19: ='泰安站'!$H11 -> 47332.8 | I19: ='泰安站'!$H12 -> 91929.6 | J19: ='泰安站'!$H13 -> 13132.8 | K19: ='泰安站'!$H14 -> 0 | L19: ='泰安站'!$H15 | M19: ='泰安站'!$H16 | N19: ='泰安站'!$H17 | O19: ='泰安站'!$H18 | P19: ='泰安站'!$H19 | Q19: =SUM(E19:P19) -> 364708.8
A20: 18 | B20: ='總表'!B20 -> 泰安 | C20: ='總表'!C20 -> 七公圳二號抽水井 | D20: ='總表'!D20 -> B1040342 | E20: ='泰安站'!$L8 -> 5726.16 | F20: ='泰安站'!$L9 -> 40256.64 | G20: ='泰安站'!$L10 -> 119121.48 | H20: ='泰安站'!$L11 -> 39736.08 | I20: ='泰安站'!$L12 -> 58302.72 | J20: ='泰安站'!$L13 -> 8328.96 | K20: ='泰安站'!$L14 -> 0 | L20: ='泰安站'!$L15 | M20: ='泰安站'!$L16 | N20: ='泰安站'!$L17 | O20: ='泰安站'!$L18 | P20: ='泰安站'!$L19 | Q20: =SUM(E20:P20) -> 271472.04
A21: 19 | B21: ='總表'!B21 -> 泰安 | C21: ='總表'!C21 -> 新店圳二號抽水井 | D21: ='總表'!D21 -> B1140020 | E21: ='泰安站'!$P8 -> 0 | F21: ='泰安站'!$P9 -> 3456 | G21: ='泰安站'!$P10 -> 68083.2 | H21: ='泰安站'!$P11 -> 30528 | I21: ='泰安站'!$P12 -> 41587.2 | J21: ='泰安站'!$P13 -> 13248 | K21: ='泰安站'!$P14 -> 0 | L21: ='泰安站'!$P15 | M21: ='泰安站'!$P16 | N21: ='泰安站'!$P17 | O21: ='泰安站'!$P18 | P21: ='泰安站'!$P19 | Q21: =SUM(E21:P21) -> 156902.4
A22: 20 | B22: ='總表'!B22 -> 泰安 | C22: ='總表'!C22 -> 新店圳三號抽水井 | D22: ='總表'!D22 -> B1140033 | E22: ='泰安站'!$T8 -> 0 | F22: ='泰安站'!$T9 -> 3024 | G22: ='泰安站'!$T10 -> 59572.8 | H22: ='泰安站'!$T11 -> 26712 | I22: ='泰安站'!$T12 -> 36388.8 | J22: ='泰安站'!$T13 -> 11592 | K22: ='泰安站'!$T14 -> 0 | L22: ='泰安站'!$T15 | M22: ='泰安站'!$T16 | N22: ='泰安站'!$T17 | O22: ='泰安站'!$T18 | P22: ='泰安站'!$T19 | Q22: =SUM(E22:P22) -> 137289.6
A23: 21 | B23: ='總表'!B23 -> 屯子腳 | C23: ='總表'!C23 -> 內埔圳一號抽水井 | D23: ='總表'!D23 -> B0970028 | E23: ='屯子腳站'!$D8 -> 0 | F23: ='屯子腳站'!$D9 -> 0 | G23: ='屯子腳站'!$D10 -> 12825 | H23: ='屯子腳站'!$D11 -> 16740 | I23: ='屯子腳站'!$D12 -> 0 | J23: ='屯子腳站'!$D13 -> 0 | K23: ='屯子腳站'!$D14 -> 0 | L23: ='屯子腳站'!$D15 | M23: ='屯子腳站'!$D16 | N23: ='屯子腳站'!$D17 | O23: ='屯子腳站'!$D18 | P23: ='屯子腳站'!$D19 | Q23: =SUM(E23:P23) -> 29565
A24: 22 | B24: ='總表'!B24 -> 屯子腳 | C24: ='總表'!C24 -> 內埔圳二號抽水井 | D24: ='總表'!D24 -> B0970027 | E24: ='屯子腳站'!$H8 -> 0 | F24: ='屯子腳站'!$H9 -> 0 | G24: ='屯子腳站'!$H10 -> 10143 | H24: ='屯子腳站'!$H11 -> 4032 | I24: ='屯子腳站'!$H12 -> 3024 | J24: ='屯子腳站'!$H13 -> 0 | K24: ='屯子腳站'!$H14 -> 0 | L24: ='屯子腳站'!$H15 | M24: ='屯子腳站'!$H16 | N24: ='屯子腳站'!$H17 | O24: ='屯子腳站'!$H18 | P24: ='屯子腳站'!$H19 | Q24: =SUM(E24:P24) -> 17199
A25: 23 | B25: ='總表'!B25 -> 屯子腳 | C25: ='總表'!C25 -> 內埔圳二支線一號抽水井 | D25: ='總表'!D25 -> B1070014 | E25: ='屯子腳站'!$L8 -> 0 | F25: ='屯子腳站'!$L9 -> 0 | G25: ='屯子腳站'!$L10 -> 6280.56 | H25: ='屯子腳站'!$L11 -> 8030.88 | I25: ='屯子腳站'!$L12 -> 5302.44 | J25: ='屯子腳站'!$L13 -> 4530.24 | K25: ='屯子腳站'!$L14 -> 0 | L25: ='屯子腳站'!$L15 | M25: ='屯子腳站'!$L16 | N25: ='屯子腳站'!$L17 | O25: ='屯子腳站'!$L18 | P25: ='屯子腳站'!$L19 | Q25: =SUM(E25:P25) -> 24144.12
A26: 24 | B26: ='總表'!B26 -> 屯子腳 | C26: ='總表'!C26 -> 內埔圳二支線二號抽水井 | D26: ='總表'!D26 -> B1100760 | E26: ='屯子腳站'!$P8 -> 0 | F26: ='屯子腳站'!$P9 -> 0 | G26: ='屯子腳站'!$P10 -> 14180.4 | H26: ='屯子腳站'!$P11 -> 14180.4 | I26: ='屯子腳站'!$P12 -> 9406.8 | J26: ='屯子腳站'!$P13 -> 6177.6 | K26: ='屯子腳站'!$P14 -> 1825.2 | L26: ='屯子腳站'!$P15 | M26: ='屯子腳站'!$P16 | N26: ='屯子腳站'!$P17 | O26: ='屯子腳站'!$P18 | P26: ='屯子腳站'!$P19 | Q26: =SUM(E26:P26) -> 45770.4
A27: 25 | B27: ='總表'!B27 -> 屯子腳 | C27: ='總表'!C27 -> 內埔圳梅仔腳溝支線水井 | D27: ='總表'!D27 -> B1140111 | E27: ='屯子腳站'!$T8 -> 0 | F27: ='屯子腳站'!$T9 -> 0 | G27: ='屯子腳站'!$T10 -> 5292 | H27: ='屯子腳站'!$T11 -> 12600 | I27: ='屯子腳站'!$T12 -> 10962 | J27: ='屯子腳站'!$T13 -> 4662 | K27: ='屯子腳站'!$T14 -> 0 | L27: ='屯子腳站'!$T15 | M27: ='屯子腳站'!$T16 | N27: ='屯子腳站'!$T17 | O27: ='屯子腳站'!$T18 | P27: ='屯子腳站'!$T19 | Q27: =SUM(E27:P27) -> 33516
A28: 26 | B28: ='總表'!B28 -> 磁瑤 | C28: ='總表'!C28 -> 后里圳一號抽水井 | D28: ='總表'!D28 -> B0112603 | E28: ='磁瑤站'!$D8 -> 496.8 | F28: ='磁瑤站'!$D9 -> 993.6 | G28: ='磁瑤站'!$D10 -> 248.4 | H28: ='磁瑤站'!$D11 -> 0 | I28: ='磁瑤站'!$D12 -> 0 | J28: ='磁瑤站'!$D13 -> 331.2 | K28: ='磁瑤站'!$D14 -> 0 | L28: ='磁瑤站'!$D15 | M28: ='磁瑤站'!$D16 | N28: ='磁瑤站'!$D17 | O28: ='磁瑤站'!$D18 | P28: ='磁瑤站'!$D19 | Q28: =SUM(E28:P28) -> 2070
A29: 27 | B29: ='總表'!B29 -> 磁瑤 | C29: ='總表'!C29 -> 后里圳三號抽水井 | D29: ='總表'!D29 -> B0930053 | E29: ='磁瑤站'!$H8 -> 288 | F29: ='磁瑤站'!$H9 -> 2073.6 | G29: ='磁瑤站'!$H10 -> 1728 | H29: ='磁瑤站'!$H11 -> 633.6 | I29: ='磁瑤站'!$H12 -> 0 | J29: ='磁瑤站'!$H13 -> 0 | K29: ='磁瑤站'!$H14 -> 259.2 | L29: ='磁瑤站'!$H15 | M29: ='磁瑤站'!$H16 | N29: ='磁瑤站'!$H17 | O29: ='磁瑤站'!$H18 | P29: ='磁瑤站'!$H19 | Q29: =SUM(E29:P29) -> 4982.4
A30: 28 | B30: ='總表'!B30 -> 磁瑤 | C30: ='總表'!C30 -> 后里圳四號抽水井 | D30: ='總表'!D30 -> B0950059 | E30: ='磁瑤站'!$L8 -> 0 | F30: ='磁瑤站'!$L9 -> 0 | G30: ='磁瑤站'!$L10 -> 0 | H30: ='磁瑤站'!$L11 -> 0 | I30: ='磁瑤站'!$L12 -> 0 | J30: ='磁瑤站'!$L13 -> 0 | K30: ='磁瑤站'!$L14 -> 0 | L30: ='磁瑤站'!$L15 | M30: ='磁瑤站'!$L16 | N30: ='磁瑤站'!$L17 | O30: ='磁瑤站'!$L18 | P30: ='磁瑤站'!$L19 | Q30: =SUM(E30:P30) -> 0
A31: 29 | B31: ='總表'!B31 -> 磁瑤 | C31: ='總表'!C31 -> 后里圳七支線二號抽水井 | D31: ='總表'!D31 -> B1070109 | E31: ='磁瑤站'!$P8 -> 4032 | F31: ='磁瑤站'!$P9 -> 392889.6 | G31: ='磁瑤站'!$P10 -> 1497.6 | H31: ='磁瑤站'!$P11 -> 691.2 | I31: ='磁瑤站'!$P12 -> 921.6 | J31: ='磁瑤站'!$P13 -> 0 | K31: ='磁瑤站'!$P14 -> 0 | L31: ='磁瑤站'!$P15 | M31: ='磁瑤站'!$P16 | N31: ='磁瑤站'!$P17 | O31: ='磁瑤站'!$P18 | P31: ='磁瑤站'!$P19 | Q31: =SUM(E31:P31) -> 400032
A32: 30 | B32: ='總表'!B32 -> 磁瑤 | C32: ='總表'!C32 -> 后里圳六支線一號抽水井 | D32: ='總表'!D32 -> B1080127 | E32: ='磁瑤站'!$T8 -> 4636.8 | F32: ='磁瑤站'!$T9 -> 4334.4 | G32: ='磁瑤站'!$T10 -> 2620.8 | H32: ='磁瑤站'!$T11 -> 604.8 | I32: ='磁瑤站'!$T12 -> 1512 | J32: ='磁瑤站'!$T13 -> 705.6 | K32: ='磁瑤站'!$T14 -> 0 | L32: ='磁瑤站'!$T15 | M32: ='磁瑤站'!$T16 | N32: ='磁瑤站'!$T17 | O32: ='磁瑤站'!$T18 | P32: ='磁瑤站'!$T19 | Q32: =SUM(E32:P32) -> 14414.4
A33: 31 | B33: ='總表'!B33 -> 磁瑤 | C33: ='總表'!C33 -> 后里圳七支線一號抽水井 | D33: ='總表'!D33 -> B1100779 | E33: ='磁瑤站'!$X8 -> 2016 | F33: ='磁瑤站'!$X9 -> 979.2 | G33: ='磁瑤站'!$X10 -> 748.8 | H33: ='磁瑤站'!$X11 -> 345.6 | I33: ='磁瑤站'!$X12 -> 345.6 | J33: ='磁瑤站'!$X13 -> 0 | K33: ='磁瑤站'!$X14 -> 0 | L33: ='磁瑤站'!$X15 | M33: ='磁瑤站'!$X16 | N33: ='磁瑤站'!$X17 | O33: ='磁瑤站'!$X18 | P33: ='磁瑤站'!$X19 | Q33: =SUM(E33:P33) -> 4435.2
A34: 32 | B34: ='總表'!B34 -> 磁瑤 | C34: ='總表'!C34 -> 后里圳二號抽水井 | D34: ='總表'!D34 -> B1140109 | E34: ='磁瑤站'!$AB8 -> 1461.6 | F34: ='磁瑤站'!$AB9 -> 501.12 | G34: ='磁瑤站'!$AB10 -> 2004.48 | H34: ='磁瑤站'!$AB11 -> 0 | I34: ='磁瑤站'!$AB12 -> 0 | J34: ='磁瑤站'!$AB13 -> 0 | K34: ='磁瑤站'!$AB14 -> 0 | L34: ='磁瑤站'!$AB15 | M34: ='磁瑤站'!$AB16 | N34: ='磁瑤站'!$AB17 | O34: ='磁瑤站'!$AB18 | P34: ='磁瑤站'!$AB19 | Q34: =SUM(E34:P34) -> 3967.2
A35: 33 | B35: ='總表'!B35 -> 磁瑤 | C35: ='總表'!C35 -> 后里圳七支線三號抽水井 | D35: ='總表'!D35 -> B1140110 | E35: ='磁瑤站'!$AF8 -> 1749.6 | F35: ='磁瑤站'!$AF9 -> 1166.4 | G35: ='磁瑤站'!$AF10 -> 1049.76 | H35: ='磁瑤站'!$AF11 -> 0 | I35: ='磁瑤站'!$AF12 -> 0 | J35: ='磁瑤站'!$AF13 -> 0 | K35: ='磁瑤站'!$AF14 -> 0 | L35: ='磁瑤站'!$AF15 | M35: ='磁瑤站'!$AF16 | N35: ='磁瑤站'!$AF17 | O35: ='磁瑤站'!$AF18 | P35: ='磁瑤站'!$AF19 | Q35: =SUM(E35:P35) -> 3965.76
A36: 34 | B36: ='總表'!B36 -> 月眉 | C36: ='總表'!C36 -> 后里圳幹線抽水井 | D36: ='總表'!D36 -> B1090023 | E36: ='月眉站'!$D8 -> 4752 | F36: ='月眉站'!$D9 -> 0 | G36: ='月眉站'!$D10 -> 6652.8 | H36: ='月眉站'!$D11 -> 3564 | I36: ='月眉站'!$D12 -> 6652.8 | J36: ='月眉站'!$D13 -> 2257.2 | K36: ='月眉站'!$D14 -> 59.4 | L36: ='月眉站'!$D15 | M36: ='月眉站'!$D16 | N36: ='月眉站'!$D17 | O36: ='月眉站'!$D18 | P36: ='月眉站'!$D19 | Q36: =SUM(E36:P36) -> 23938.2
A37: 35 | B37: ='總表'!B37 -> 月眉 | C37: ='總表'!C37 -> 月眉站舊辦公廳地下水抽水井 | D37: ='總表'!D37 -> B0130304 | E37: ='月眉站'!$H8 -> 0 | F37: ='月眉站'!$H9 -> 0 | G37: ='月眉站'!$H10 -> 0 | H37: ='月眉站'!$H11 -> 0 | I37: ='月眉站'!$H12 -> 0 | J37: ='月眉站'!$H13 -> 0 | K37: ='月眉站'!$H14 -> 0 | L37: ='月眉站'!$H15 | M37: ='月眉站'!$H16 | N37: ='月眉站'!$H17 | O37: ='月眉站'!$H18 | P37: ='月眉站'!$H19 | Q37: =SUM(E37:P37) -> 0
A38: 36 | B38: ='總表'!B38 -> 月眉 | C38: ='總表'!C38 -> 后里圳月眉排水補給抽水井 | D38: ='總表'!D38 -> B1070176 | E38: ='月眉站'!$L8 -> 3672 | F38: ='月眉站'!$L9 -> 3672 | G38: ='月眉站'!$L10 -> 7344 | H38: ='月眉站'!$L11 -> 3672 | I38: ='月眉站'!$L12 -> 7344 | J38: ='月眉站'!$L13 -> 2448 | K38: ='月眉站'!$L14 -> 61.2 | L38: ='月眉站'!$L15 | M38: ='月眉站'!$L16 | N38: ='月眉站'!$L17 | O38: ='月眉站'!$L18 | P38: ='月眉站'!$L19 | Q38: =SUM(E38:P38) -> 28213.2
A39: 37 | B39: ='總表'!B39 -> 月眉 | C39: ='總表'!C39 -> 后里圳三支線上游補給抽水井 | D39: ='總表'!D39 -> B1060117 | E39: ='月眉站'!$P8 -> 10368 | F39: ='月眉站'!$P9 -> 6480 | G39: ='月眉站'!$P10 -> 11016 | H39: ='月眉站'!$P11 -> 3888 | I39: ='月眉站'!$P12 -> 10368 | J39: ='月眉站'!$P13 -> 3369.6 | K39: ='月眉站'!$P14 -> 64.8 | L39: ='月眉站'!$P15 | M39: ='月眉站'!$P16 | N39: ='月眉站'!$P17 | O39: ='月眉站'!$P18 | P39: ='月眉站'!$P19 | Q39: =SUM(E39:P39) -> 45554.4
A40: 38 | B40: ='總表'!B40 -> 月眉 | C40: ='總表'!C40 -> 后里圳三支線中游補給抽水井 | D40: ='總表'!D40 -> B1040345 | E40: ='月眉站'!$T8 -> 0 | F40: ='月眉站'!$T9 -> 0 | G40: ='月眉站'!$T10 -> 0 | H40: ='月眉站'!$T11 -> 594 | I40: ='月眉站'!$T12 -> 4158 | J40: ='月眉站'!$T13 -> 1425.6 | K40: ='月眉站'!$T14 -> 59.4 | L40: ='月眉站'!$T15 | M40: ='月眉站'!$T16 | N40: ='月眉站'!$T17 | O40: ='月眉站'!$T18 | P40: ='月眉站'!$T19 | Q40: =SUM(E40:P40) -> 6237
A41: 39 | B41: ='總表'!B41 -> 月眉 | C41: ='總表'!C41 -> 后里圳三支線中游二號抽水井 | D41: ='總表'!D41 -> B1100675 | E41: ='月眉站'!$X8 -> 3715.2 | F41: ='月眉站'!$X9 -> 3467.52 | G41: ='月眉站'!$X10 -> 4334.4 | H41: ='月眉站'!$X11 -> 4953.6 | I41: ='月眉站'!$X12 -> 4953.6 | J41: ='月眉站'!$X13 -> 1609.92 | K41: ='月眉站'!$X14 -> 61.92 | L41: ='月眉站'!$X15 | M41: ='月眉站'!$X16 | N41: ='月眉站'!$X17 | O41: ='月眉站'!$X18 | P41: ='月眉站'!$X19 | Q41: =SUM(E41:P41) -> 23096.16
...

Sheet 卓蘭站
A1: 站別- | B1: 卓蘭
A2: 年度別- | B2: 115
A3: 抽水井名稱- | B3: ='總表'!$C3 -> 苗豐抽水井
A4: 水權狀號- | B4: ='總表'!$D3 -> K0124239
A5: 核准年限- | B5: ='總表'!$E3 -> 1120808 | C5: ='總表'!$F3 -> 1170807
A6: 備註- | B6: ='總表'!$K3 -> 16 | C6: 小時/日
A7: 項目 月份 | B7: 抽水時間(hr) | C7: 水權引水量(cms) | D7: 抽水量(m³)
A8: 1 | B8: 0.433 | C8: ='總表'!$J3 -> 0.0169 | D8: =IF(B8="","",B8*C8*3600) -> 26.34372
A9: 2 | B9: 13.17 | C9: =C8 -> 0.0169 | D9: =IF(B9="","",B9*C9*3600) -> 801.2628
A10: 3 | B10: 37.08 | C10: =C8 -> 0.0169 | D10: =IF(B10="","",B10*C10*3600) -> 2255.9472
A11: 4 | B11: 0.1666666 | C11: =C8 -> 0.0169 | D11: =IF(B11="","",B11*C11*3600) -> 10.139996
A12: 5 | B12: 0 | C12: =C8 -> 0.0169 | D12: =IF(B12="","",B12*C12*3600) -> 0
A13: 6 | B13: 27.6 | C13: =C8 -> 0.0169 | D13: =IF(B13="","",B13*C13*3600) -> 1679.184
A14: 7 | B14: 14.89999 | C14: =C8 -> 0.0169 | D14: =IF(B14="","",B14*C14*3600) -> 906.51539
A15: 8 | C15: =C8 -> 0.0169 | D15: =IF(B15="","",B15*C15*3600)
A16: 9 | C16: =C8 -> 0.0169 | D16: =IF(B16="","",B16*C16*3600)
A17: 10 | C17: =C8 -> 0.0169 | D17: =IF(B17="","",B17*C17*3600)
A18: 11 | C18: =C8 -> 0.0169 | D18: =IF(B18="","",B18*C18*3600)
A19: 12 | C19: =C8 -> 0.0169 | D19: =IF(B19="","",B19*C19*3600)
A20: 合計 | D20: =SUM(D8:D19) -> 5679.3931

Sheet 苑裡站
A1: 站別- | B1: 苑裡 | E1: 站別- | F1: =$B$1 -> 苑裡 | I1: 站別- | J1: =$B$1 -> 苑裡 | M1: 站別- | N1: =$B$1 -> 苑裡 | Q1: 站別- | R1: =$B$1 -> 苑裡 | U1: 站別- | V1: =$B$1 -> 苑裡
A2: 年度別- | B2: ='卓蘭站'!B2 -> 115 | E2: 年度別- | F2: ='卓蘭站'!B2 -> 115 | I2: 年度別- | J2: ='卓蘭站'!B2 -> 115 | M2: 年度別- | N2: ='卓蘭站'!B2 -> 115 | Q2: 年度別- | R2: ='卓蘭站'!B2 -> 115 | U2: 年度別- | V2: ='卓蘭站'!B2 -> 115
A3: 抽水井名稱- | B3: ='總表'!C12 -> 新復一號抽水井 | E3: 抽水井名稱- | F3: ='總表'!$C13 -> 新復二號抽水井 | I3: 抽水井名稱- | J3: ='總表'!$C14 -> 田心小組抽水井 | M3: 抽水井名稱- | N3: ='總表'!$C15 -> 田心二號抽水井 | Q3: 抽水井名稱- | R3: ='總表'!$C16 -> 西勢支線抽水井 | U3: 抽水井名稱- | V3: ='總表'!$C17 -> 砂埤支線抽水井
A4: 水權狀號- | B4: ='總表'!$D12 -> K0123688 | E4: 水權狀號- | F4: ='總表'!$D13 -> K0123786 | I4: 水權狀號- | J4: ='總表'!$D14 -> K0123766 | M4: 水權狀號- | N4: ='總表'!$D15 -> K0124420 | Q4: 水權狀號- | R4: ='總表'!$D16 -> K0123779 | U4: 水權狀號- | V4: ='總表'!$D17 -> K0124485
A5: 核准年限- | B5: ='總表'!$E12 -> 1110101 | C5: ='總表'!$F12 -> 1151231 | E5: 核准年限- | F5: ='總表'!$E13 -> 1130201 | G5: ='總表'!$F13 -> 1180131 | I5: 核准年限- | J5: ='總表'!$E14 -> 1121201 | K5: ='總表'!$F14 -> 1171130 | M5: 核准年限- | N5: ='總表'!$E15 -> 1140401 | O5: ='總表'!$F15 -> 1190331 | Q5: 核准年限- | R5: ='總表'!$E16 -> 1130201 | S5: ='總表'!$F16 -> 1180131 | U5: 核准年限- | V5: ='總表'!$E17 -> 1140901 | W5: ='總表'!$F17 -> 1190831
A6: 備註- | B6: ='總表'!$K12 -> 20 | C6: 小時/日 | E6: 備註- | F6: ='總表'!$K13 -> 20 | G6: 小時/日 | I6: 備註- | J6: ='總表'!$K14 -> 20 | K6: 小時/日 | M6: 備註- | N6: ='總表'!$K15 -> 20 | O6: 小時/日 | Q6: 備註- | R6: ='總表'!$K16 -> 20 | S6: 小時/日 | U6: 備註- | V6: ='總表'!$K17 -> 20 | W6: 小時/日
A7: 項目 月份 | B7: 抽水時間(hr) | C7: 水權引水量(cms) | D7: 抽水量(m³) | E7: 項目 月份 | F7: 抽水時間(hr) | G7: 水權引水量(cms) | H7: 抽水量(m³) | I7: 項目 月份 | J7: 抽水時間(hr) | K7: 水權引水量(cms) | L7: 抽水量(m³) | M7: 項目 月份 | N7: 抽水時間(hr) | O7: 水權引水量(cms) | P7: 抽水量(m³) | Q7: 項目 月份 | R7: 抽水時間(hr) | S7: 水權引水量(cms) | T7: 抽水量(m³) | U7: 項目 月份 | V7: 抽水時間(hr) | W7: 水權引水量(cms) | X7: 抽水量(m³)
A8: 1 | B8: 0 | C8: ='總表'!$J12 -> 0.0613 | D8: =IF(B8="","",B8*C8*3600) -> 0 | E8: 1 | F8: 0 | G8: ='總表'!$J13 -> 0.038 | H8: =IF(F8="","",F8*G8*3600) -> 0 | I8: 1 | J8: 0 | K8: ='總表'!$J14 -> 0.07 | L8: =IF(J8="","",J8*K8*3600) -> 0 | M8: 1 | N8: 0 | O8: ='總表'!$J15 -> 0.0525 | P8: =IF(N8="","",N8*O8*3600) -> 0 | Q8: 1 | R8: 0 | S8: ='總表'!$J16 -> 0.0175 | T8: =IF(R8="","",R8*S8*3600) -> 0 | U8: 1 | V8: 0 | W8: ='總表'!$J17 -> 0.025 | X8: =IF(V8="","",V8*W8*3600) -> 0
A9: 2 | B9: 240 | C9: =C8 -> 0.0613 | D9: =IF(B9="","",B9*C9*3600) -> 52963.2 | E9: 2 | F9: 240 | G9: =G8 -> 0.038 | H9: =IF(F9="","",F9*G9*3600) -> 32832 | I9: 2 | J9: 204 | K9: =K8 -> 0.07 | L9: =IF(J9="","",J9*K9*3600) -> 51408 | M9: 2 | N9: 197 | O9: =O8 -> 0.0525 | P9: =IF(N9="","",N9*O9*3600) -> 37233 | Q9: 2 | R9: 72 | S9: =S8 -> 0.0175 | T9: =IF(R9="","",R9*S9*3600) -> 4536 | U9: 2 | V9: 216 | W9: =W8 -> 0.025 | X9: =IF(V9="","",V9*W9*3600) -> 19440
A10: 3 | B10: 312 | C10: =C8 -> 0.0613 | D10: =IF(B10="","",B10*C10*3600) -> 68852.16 | E10: 3 | F10: 312 | G10: =G8 -> 0.038 | H10: =IF(F10="","",F10*G10*3600) -> 42681.6 | I10: 3 | J10: 434 | K10: =K8 -> 0.07 | L10: =IF(J10="","",J10*K10*3600) -> 109368 | M10: 3 | N10: 434 | O10: =O8 -> 0.0525 | P10: =IF(N10="","",N10*O10*3600) -> 82026 | Q10: 3 | R10: 294 | S10: =S8 -> 0.0175 | T10: =IF(R10="","",R10*S10*3600) -> 18522 | U10: 3 | V10: 398 | W10: =W8 -> 0.025 | X10: =IF(V10="","",V10*W10*3600) -> 35820
A11: 4 | B11: 149 | C11: =C8 -> 0.0613 | D11: =IF(B11="","",B11*C11*3600) -> 32881.32 | E11: 4 | F11: 192 | G11: =G8 -> 0.038 | H11: =IF(F11="","",F11*G11*3600) -> 26265.6 | I11: 4 | J11: 149 | K11: =K8 -> 0.07 | L11: =IF(J11="","",J11*K11*3600) -> 37548 | M11: 4 | N11: 149 | O11: =O8 -> 0.0525 | P11: =IF(N11="","",N11*O11*3600) -> 28161 | Q11: 4 | R11: 75 | S11: =S8 -> 0.0175 | T11: =IF(R11="","",R11*S11*3600) -> 4725 | U11: 4 | V11: 192 | W11: =W8 -> 0.025 | X11: =IF(V11="","",V11*W11*3600) -> 17280
A12: 5 | B12: 188 | C12: =C8 -> 0.0613 | D12: =IF(B12="","",B12*C12*3600) -> 41487.84 | E12: 5 | F12: 231 | G12: =G8 -> 0.038 | H12: =IF(F12="","",F12*G12*3600) -> 31600.8 | I12: 5 | J12: 110 | K12: =K8 -> 0.07 | L12: =IF(J12="","",J12*K12*3600) -> 27720 | M12: 5 | N12: 176 | O12: =O8 -> 0.0525 | P12: =IF(N12="","",N12*O12*3600) -> 33264 | Q12: 5 | R12: 92 | S12: =S8 -> 0.0175 | T12: =IF(R12="","",R12*S12*3600) -> 5796 | U12: 5 | V12: 110 | W12: =W8 -> 0.025 | X12: =IF(V12="","",V12*W12*3600) -> 9900
A13: 6 | B13: 167 | C13: =C8 -> 0.0613 | D13: =IF(B13="","",B13*C13*3600) -> 36853.56 | E13: 6 | F13: 167 | G13: =G8 -> 0.038 | H13: =IF(F13="","",F13*G13*3600) -> 22845.6 | I13: 6 | J13: 167 | K13: =K8 -> 0.07 | L13: =IF(J13="","",J13*K13*3600) -> 42084 | M13: 6 | N13: 167 | O13: =O8 -> 0.0525 | P13: =IF(N13="","",N13*O13*3600) -> 31563 | Q13: 6 | R13: 48 | S13: =S8 -> 0.0175 | T13: =IF(R13="","",R13*S13*3600) -> 3024 | U13: 6 | V13: 167 | W13: =W8 -> 0.025 | X13: =IF(V13="","",V13*W13*3600) -> 15030
A14: 7 | B14: 0 | C14: =C8 -> 0.0613 | D14: =IF(B14="","",B14*C14*3600) -> 0 | E14: 7 | F14: 0 | G14: =G8 -> 0.038 | H14: =IF(F14="","",F14*G14*3600) -> 0 | I14: 7 | J14: 0 | K14: =K8 -> 0.07 | L14: =IF(J14="","",J14*K14*3600) -> 0 | M14: 7 | N14: 0 | O14: =O8 -> 0.0525 | P14: =IF(N14="","",N14*O14*3600) -> 0 | Q14: 7 | R14: 0 | S14: =S8 -> 0.0175 | T14: =IF(R14="","",R14*S14*3600) -> 0 | U14: 7 | V14: 0 | W14: =W8 -> 0.025 | X14: =IF(V14="","",V14*W14*3600) -> 0
A15: 8 | C15: =C8 -> 0.0613 | D15: =IF(B15="","",B15*C15*3600) | E15: 8 | G15: =G8 -> 0.038 | H15: =IF(F15="","",F15*G15*3600) | I15: 8 | K15: =K8 -> 0.07 | L15: =IF(J15="","",J15*K15*3600) | M15: 8 | O15: =O8 -> 0.0525 | P15: =IF(N15="","",N15*O15*3600) | Q15: 8 | S15: =S8 -> 0.0175 | T15: =IF(R15="","",R15*S15*3600) | U15: 8 | W15: =W8 -> 0.025 | X15: =IF(V15="","",V15*W15*3600)
A16: 9 | C16: =C8 -> 0.0613 | D16: =IF(B16="","",B16*C16*3600) | E16: 9 | G16: =G8 -> 0.038 | H16: =IF(F16="","",F16*G16*3600) | I16: 9 | K16: =K8 -> 0.07 | L16: =IF(J16="","",J16*K16*3600) | M16: 9 | O16: =O8 -> 0.0525 | P16: =IF(N16="","",N16*O16*3600) | Q16: 9 | S16: =S8 -> 0.0175 | T16: =IF(R16="","",R16*S16*3600) | U16: 9 | W16: =W8 -> 0.025 | X16: =IF(V16="","",V16*W16*3600)
A17: 10 | C17: =C8 -> 0.0613 | D17: =IF(B17="","",B17*C17*3600) | E17: 10 | G17: =G8 -> 0.038 | H17: =IF(F17="","",F17*G17*3600) | I17: 10 | K17: =K8 -> 0.07 | L17: =IF(J17="","",J17*K17*3600) | M17: 10 | O17: =O8 -> 0.0525 | P17: =IF(N17="","",N17*O17*3600) | Q17: 10 | S17: =S8 -> 0.0175 | T17: =IF(R17="","",R17*S17*3600) | U17: 10 | W17: =W8 -> 0.025 | X17: =IF(V17="","",V17*W17*3600)
A18: 11 | C18: =C8 -> 0.0613 | D18: =IF(B18="","",B18*C18*3600) | E18: 11 | G18: =G8 -> 0.038 | H18: =IF(F18="","",F18*G18*3600) | I18: 11 | K18: =K8 -> 0.07 | L18: =IF(J18="","",J18*K18*3600) | M18: 11 | O18: =O8 -> 0.0525 | P18: =IF(N18="","",N18*O18*3600) | Q18: 11 | S18: =S8 -> 0.0175 | T18: =IF(R18="","",R18*S18*3600) | U18: 11 | W18: =W8 -> 0.025 | X18: =IF(V18="","",V18*W18*3600)
A19: 12 | C19: =C8 -> 0.0613 | D19: =IF(B19="","",B19*C19*3600) | E19: 12 | G19: =G8 -> 0.038 | H19: =IF(F19="","",F19*G19*3600) | I19: 12 | K19: =K8 -> 0.07 | L19: =IF(J19="","",J19*K19*3600) | M19: 12 | O19: =O8 -> 0.0525 | P19: =IF(N19="","",N19*O19*3600) | Q19: 12 | S19: =S8 -> 0.0175 | T19: =IF(R19="","",R19*S19*3600) | U19: 12 | W19: =W8 -> 0.025 | X19: =IF(V19="","",V19*W19*3600)
A20: 合計 | D20: =SUM(D8:D19) -> 233038.08 | E20: 合計 | H20: =SUM(H8:H19) -> 156225.6 | I20: 合計 | L20: =SUM(L8:L19) -> 268128 | M20: 合計 | P20: =SUM(P8:P19) -> 212247 | Q20: 合計 | T20: =SUM(T8:T19) -> 36603 | U20: 合計 | X20: =SUM(X8:X19) -> 97470

Sheet 山腳站
A1: 站別- | B1: 山腳 | E1: 站別- | F1: =$B$1 -> 山腳 | I1: 站別- | J1: =$B$1 -> 山腳 | M1: 站別- | N1: =$B$1 -> 山腳 | Q1: 站別- | R1: =$B$1 -> 山腳 | U1: 站別- | V1: =$B$1 -> 山腳 | Y1: 站別- | Z1: =$B$1 -> 山腳 | AC1: 站別- | AD1: =$B$1 -> 山腳
A2: 年度別- | B2: ='卓蘭站'!B2 -> 115 | E2: 年度別- | F2: ='卓蘭站'!B2 -> 115 | I2: 年度別- | J2: ='卓蘭站'!B2 -> 115 | M2: 年度別- | N2: ='卓蘭站'!B2 -> 115 | Q2: 年度別- | R2: ='卓蘭站'!B2 -> 115 | U2: 年度別- | V2: ='卓蘭站'!B2 -> 115 | Y2: 年度別- | Z2: ='卓蘭站'!B2 -> 115 | AC2: 年度別- | AD2: ='卓蘭站'!B2 -> 115
A3: 抽水井名稱- | B3: ='總表'!$C4 -> 泰田抽水井 | E3: 抽水井名稱- | F3: ='總表'!$C5 -> 社柑抽水井 | I3: 抽水井名稱- | J3: ='總表'!$C6 -> 社南抽水井 | M3: 抽水井名稱- | N3: ='總表'!$C7 -> 濁一抽水井 | Q3: 抽水井名稱- | R3: ='總表'!$C8 -> 啟心抽水井 | U3: 抽水井名稱- | V3: ='總表'!$C9 -> 山柑一號抽水井 | Y3: 抽水井名稱- | Z3: ='總表'!$C10 -> 山柑二號抽水井 | AC3: 抽水井名稱- | AD3: ='總表'!C11 -> 濁水二號抽水井
A4: 水權狀號- | B4: ='總表'!$D4 -> K0086033 | E4: 水權狀號- | F4: ='總表'!$D5 -> K0086034 | I4: 水權狀號- | J4: ='總表'!$D6 -> K0123393 | M4: 水權狀號- | N4: ='總表'!$D7 -> K0123725 | Q4: 水權狀號- | R4: ='總表'!$D8 -> K0123768 | U4: 水權狀號- | V4: ='總表'!$D9 -> K1140087 | Y4: 水權狀號- | Z4: ='總表'!$D10 -> K0124362 | AC4: 水權狀號- | AD4: ='總表'!D11 -> K1140122
A5: 核准年限- | B5: ='總表'!$E4 -> 1110401 | C5: ='總表'!$F4 -> 1160331 | E5: 核准年限- | F5: ='總表'!$E5 -> 1110401 | G5: ='總表'!$F5 -> 1160331 | I5: 核准年限- | J5: ='總表'!$E6 -> 1111101 | K5: ='總表'!$F6 -> 1161031 | M5: 核准年限- | N5: ='總表'!$E7 -> 1110101 | O5: ='總表'!$F7 -> 1151231 | Q5: 核准年限- | R5: ='總表'!$E8 -> 1121201 | S5: ='總表'!$F8 -> 1171130 | U5: 核准年限- | V5: ='總表'!$E9 -> 1140811 | W5: ='總表'!$F9 -> 1190810 | Y5: 核准年限- | Z5: ='總表'!$E10 -> 1130711 | AA5: ='總表'!$F10 -> 1180710 | AC5: 核准年限- | AD5: ='總表'!E11 -> 1141011 | AE5: ='總表'!F11 -> 1191010
A6: 備註- | B6: ='總表'!$K4 -> 20 | C6: 小時/日 | E6: 備註- | F6: ='總表'!$K5 -> 20 | G6: 小時/日 | I6: 備註- | J6: ='總表'!$K6 -> 20 | K6: 小時/日 | M6: 備註- | N6: ='總表'!$K7 -> 20 | O6: 小時/日 | Q6: 備註- | R6: ='總表'!$K8 -> 20 | S6: 小時/日 | U6: 備註- | V6: ='總表'!$K9 -> 20 | W6: 小時/日 | Y6: 備註- | Z6: ='總表'!$K10 -> 20 | AA6: 小時/日 | AC6: 備註- | AD6: ='總表'!K11 -> 20 | AE6: 小時/日
A7: 項目 月份 | B7: 抽水時間(hr) | C7: 水權引水量(cms) | D7: 抽水量(m³) | E7: 項目 月份 | F7: 抽水時間(hr) | G7: 水權引水量(cms) | H7: 抽水量(m³) | I7: 項目 月份 | J7: 抽水時間(hr) | K7: 水權引水量(cms) | L7: 抽水量(m³) | M7: 項目 月份 | N7: 抽水時間(hr) | O7: 水權引水量(cms) | P7: 抽水量(m³) | Q7: 項目 月份 | R7: 抽水時間(hr) | S7: 水權引水量(cms) | T7: 抽水量(m³) | U7: 項目 月份 | V7: 抽水時間(hr) | W7: 水權引水量(cms) | X7: 抽水量(m³) | Y7: 項目 月份 | Z7: 抽水時間(hr) | AA7: 水權引水量(cms) | AB7: 抽水量(m³) | AC7: 項目 月份 | AD7: 抽水時間(hr) | AE7: 水權引水量(cms) | AF7: 抽水量(m³)
A8: 1 | B8: 0 | C8: ='總表'!$J4 -> 0.0136 | D8: =IF(B8="","",B8*C8*3600) -> 0 | E8: 1 | F8: 2 | G8: ='總表'!$J5 -> 0.042 | H8: =IF(F8="","",F8*G8*3600) -> 302.4 | I8: 1 | J8: 2 | K8: ='總表'!$J6 -> 0.016 | L8: =IF(J8="","",J8*K8*3600) -> 115.2 | M8: 1 | N8: 2 | O8: ='總表'!$J7 -> 0.038 | P8: =IF(N8="","",N8*O8*3600) -> 273.6 | Q8: 1 | R8: 2 | S8: ='總表'!$J8 -> 0.03 | T8: =IF(R8="","",R8*S8*3600) -> 216 | U8: 1 | V8: 0 | W8: ='總表'!$J9 -> 0.035 | X8: =IF(V8="","",V8*W8*3600) -> 0 | Y8: 1 | Z8: 2 | AA8: ='總表'!$J10 -> 0.035 | AB8: =IF(Z8="","",Z8*AA8*3600) -> 252 | AC8: 1 | AD8: 0 | AE8: ='總表'!J11 -> 0.023 | AF8: =IF(AD8="","",AD8*AE8*3600) -> 0
A9: 2 | B9: 0 | C9: =C8 -> 0.0136 | D9: =IF(B9="","",B9*C9*3600) -> 0 | E9: 2 | F9: 144 | G9: =G8 -> 0.042 | H9: =IF(F9="","",F9*G9*3600) -> 21772.8 | I9: 2 | J9: 144 | K9: =K8 -> 0.016 | L9: =IF(J9="","",J9*K9*3600) -> 8294.4 | M9: 2 | N9: 144 | O9: =O8 -> 0.038 | P9: =IF(N9="","",N9*O9*3600) -> 19699.2 | Q9: 2 | R9: 126 | S9: =S8 -> 0.03 | T9: =IF(R9="","",R9*S9*3600) -> 13608 | U9: 2 | V9: 0 | W9: =W8 -> 0.035 | X9: =IF(V9="","",V9*W9*3600) -> 0 | Y9: 2 | Z9: 144 | AA9: =AA8 -> 0.035 | AB9: =IF(Z9="","",Z9*AA9*3600) -> 18144 | AC9: 2 | AD9: 0 | AE9: =AE8 -> 0.023 | AF9: =IF(AD9="","",AD9*AE9*3600) -> 0
A10: 3 | B10: 0 | C10: =C8 -> 0.0136 | D10: =IF(B10="","",B10*C10*3600) -> 0 | E10: 3 | F10: 255 | G10: =G8 -> 0.042 | H10: =IF(F10="","",F10*G10*3600) -> 38556 | I10: 3 | J10: 255 | K10: =K8 -> 0.016 | L10: =IF(J10="","",J10*K10*3600) -> 14688 | M10: 3 | N10: 145 | O10: =O8 -> 0.038 | P10: =IF(N10="","",N10*O10*3600) -> 19836 | Q10: 3 | R10: 104 | S10: =S8 -> 0.03 | T10: =IF(R10="","",R10*S10*3600) -> 11232 | U10: 3 | V10: 0 | W10: =W8 -> 0.035 | X10: =IF(V10="","",V10*W10*3600) -> 0 | Y10: 3 | Z10: 160 | AA10: =AA8 -> 0.035 | AB10: =IF(Z10="","",Z10*AA10*3600) -> 20160 | AC10: 3 | AD10: 0 | AE10: =AE8 -> 0.023 | AF10: =IF(AD10="","",AD10*AE10*3600) -> 0
A11: 4 | B11: 0 | C11: =C8 -> 0.0136 | D11: =IF(B11="","",B11*C11*3600) -> 0 | E11: 4 | F11: 110 | G11: =G8 -> 0.042 | H11: =IF(F11="","",F11*G11*3600) -> 16632 | I11: 4 | J11: 140 | K11: =K8 -> 0.016 | L11: =IF(J11="","",J11*K11*3600) -> 8064 | M11: 4 | N11: 48 | O11: =O8 -> 0.038 | P11: =IF(N11="","",N11*O11*3600) -> 6566.4 | Q11: 4 | R11: 48 | S11: =S8 -> 0.03 | T11: =IF(R11="","",R11*S11*3600) -> 5184 | U11: 4 | V11: 1 | W11: =W8 -> 0.035 | X11: =IF(V11="","",V11*W11*3600) -> 126 | Y11: 4 | Z11: 16 | AA11: =AA8 -> 0.035 | AB11: =IF(Z11="","",Z11*AA11*3600) -> 2016 | AC11: 4 | AD11: 0 | AE11: =AE8 -> 0.023 | AF11: =IF(AD11="","",AD11*AE11*3600) -> 0
A12: 5 | B12: 0 | C12: =C8 -> 0.0136 | D12: =IF(B12="","",B12*C12*3600) -> 0 | E12: 5 | F12: 120 | G12: =G8 -> 0.042 | H12: =IF(F12="","",F12*G12*3600) -> 18144 | I12: 5 | J12: 140 | K12: =K8 -> 0.016 | L12: =IF(J12="","",J12*K12*3600) -> 8064 | M12: 5 | N12: 8 | O12: =O8 -> 0.038 | P12: =IF(N12="","",N12*O12*3600) -> 1094.4 | Q12: 5 | R12: 0 | S12: =S8 -> 0.03 | T12: =IF(R12="","",R12*S12*3600) -> 0 | U12: 5 | V12: 5 | W12: =W8 -> 0.035 | X12: =IF(V12="","",V12*W12*3600) -> 630 | Y12: 5 | Z12: 21 | AA12: =AA8 -> 0.035 | AB12: =IF(Z12="","",Z12*AA12*3600) -> 2646 | AC12: 5 | AD12: 0 | AE12: =AE8 -> 0.023 | AF12: =IF(AD12="","",AD12*AE12*3600) -> 0
A13: 6 | B13: 0 | C13: =C8 -> 0.0136 | D13: =IF(B13="","",B13*C13*3600) -> 0 | E13: 6 | F13: 100 | G13: =G8 -> 0.042 | H13: =IF(F13="","",F13*G13*3600) -> 15120 | I13: 6 | J13: 110 | K13: =K8 -> 0.016 | L13: =IF(J13="","",J13*K13*3600) -> 6336 | M13: 6 | N13: 8 | O13: =O8 -> 0.038 | P13: =IF(N13="","",N13*O13*3600) -> 1094.4 | Q13: 6 | R13: 0 | S13: =S8 -> 0.03 | T13: =IF(R13="","",R13*S13*3600) -> 0 | U13: 6 | V13: 8 | W13: =W8 -> 0.035 | X13: =IF(V13="","",V13*W13*3600) -> 1008 | Y13: 6 | Z13: 24 | AA13: =AA8 -> 0.035 | AB13: =IF(Z13="","",Z13*AA13*3600) -> 3024 | AC13: 6 | AD13: 4 | AE13: =AE8 -> 0.023 | AF13: =IF(AD13="","",AD13*AE13*3600) -> 331.2
A14: 7 | B14: 0 | C14: =C8 -> 0.0136 | D14: =IF(B14="","",B14*C14*3600) -> 0 | E14: 7 | F14: 100 | G14: =G8 -> 0.042 | H14: =IF(F14="","",F14*G14*3600) -> 15120 | I14: 7 | J14: 110 | K14: =K8 -> 0.016 | L14: =IF(J14="","",J14*K14*3600) -> 6336 | M14: 7 | N14: 8 | O14: =O8 -> 0.038 | P14: =IF(N14="","",N14*O14*3600) -> 1094.4 | Q14: 7 | R14: 0 | S14: =S8 -> 0.03 | T14: =IF(R14="","",R14*S14*3600) -> 0 | U14: 7 | V14: 8 | W14: =W8 -> 0.035 | X14: =IF(V14="","",V14*W14*3600) -> 1008 | Y14: 7 | Z14: 120 | AA14: =AA8 -> 0.035 | AB14: =IF(Z14="","",Z14*AA14*3600) -> 15120 | AC14: 7 | AD14: 7 | AE14: =AE8 -> 0.023 | AF14: =IF(AD14="","",AD14*AE14*3600) -> 579.6
A15: 8 | C15: =C8 -> 0.0136 | D15: =IF(B15="","",B15*C15*3600) | E15: 8 | G15: =G8 -> 0.042 | H15: =IF(F15="","",F15*G15*3600) | I15: 8 | K15: =K8 -> 0.016 | L15: =IF(J15="","",J15*K15*3600) | M15: 8 | O15: =O8 -> 0.038 | P15: =IF(N15="","",N15*O15*3600) | Q15: 8 | S15: =S8 -> 0.03 | T15: =IF(R15="","",R15*S15*3600) | U15: 8 | W15: =W8 -> 0.035 | X15: =IF(V15="","",V15*W15*3600) | Y15: 8 | AA15: =AA8 -> 0.035 | AB15: =IF(Z15="","",Z15*AA15*3600) | AC15: 8 | AE15: =AE8 -> 0.023 | AF15: =IF(AD15="","",AD15*AE15*3600)
A16: 9 | C16: =C8 -> 0.0136 | D16: =IF(B16="","",B16*C16*3600) | E16: 9 | G16: =G8 -> 0.042 | H16: =IF(F16="","",F16*G16*3600) | I16: 9 | K16: =K8 -> 0.016 | L16: =IF(J16="","",J16*K16*3600) | M16: 9 | O16: =O8 -> 0.038 | P16: =IF(N16="","",N16*O16*3600) | Q16: 9 | S16: =S8 -> 0.03 | T16: =IF(R16="","",R16*S16*3600) | U16: 9 | W16: =W8 -> 0.035 | X16: =IF(V16="","",V16*W16*3600) | Y16: 9 | AA16: =AA8 -> 0.035 | AB16: =IF(Z16="","",Z16*AA16*3600) | AC16: 9 | AE16: =AE8 -> 0.023 | AF16: =IF(AD16="","",AD16*AE16*3600)
A17: 10 | C17: =C8 -> 0.0136 | D17: =IF(B17="","",B17*C17*3600) | E17: 10 | G17: =G8 -> 0.042 | H17: =IF(F17="","",F17*G17*3600) | I17: 10 | K17: =K8 -> 0.016 | L17: =IF(J17="","",J17*K17*3600) | M17: 10 | O17: =O8 -> 0.038 | P17: =IF(N17="","",N17*O17*3600) | Q17: 10 | S17: =S8 -> 0.03 | T17: =IF(R17="","",R17*S17*3600) | U17: 10 | W17: =W8 -> 0.035 | X17: =IF(V17="","",V17*W17*3600) | Y17: 10 | AA17: =AA8 -> 0.035 | AB17: =IF(Z17="","",Z17*AA17*3600) | AC17: 10 | AE17: =AE8 -> 0.023 | AF17: =IF(AD17="","",AD17*AE17*3600)
A18: 11 | C18: =C8 -> 0.0136 | D18: =IF(B18="","",B18*C18*3600) | E18: 11 | G18: =G8 -> 0.042 | H18: =IF(F18="","",F18*G18*3600) | I18: 11 | K18: =K8 -> 0.016 | L18: =IF(J18="","",J18*K18*3600) | M18: 11 | O18: =O8 -> 0.038 | P18: =IF(N18="","",N18*O18*3600) | Q18: 11 | S18: =S8 -> 0.03 | T18: =IF(R18="","",R18*S18*3600) | U18: 11 | W18: =W8 -> 0.035 | X18: =IF(V18="","",V18*W18*3600) | Y18: 11 | AA18: =AA8 -> 0.035 | AB18: =IF(Z18="","",Z18*AA18*3600) | AC18: 11 | AE18: =AE8 -> 0.023 | AF18: =IF(AD18="","",AD18*AE18*3600)
A19: 12 | C19: =C8 -> 0.0136 | D19: =IF(B19="","",B19*C19*3600) | E19: 12 | G19: =G8 -> 0.042 | H19: =IF(F19="","",F19*G19*3600) | I19: 12 | K19: =K8 -> 0.016 | L19: =IF(J19="","",J19*K19*3600) | M19: 12 | O19: =O8 -> 0.038 | P19: =IF(N19="","",N19*O19*3600) | Q19: 12 | S19: =S8 -> 0.03 | T19: =IF(R19="","",R19*S19*3600) | U19: 12 | W19: =W8 -> 0.035 | X19: =IF(V19="","",V19*W19*3600) | Y19: 12 | AA19: =AA8 -> 0.035 | AB19: =IF(Z19="","",Z19*AA19*3600) | AC19: 12 | AE19: =AE8 -> 0.023 | AF19: =IF(AD19="","",AD19*AE19*3600)
A20: 合計 | D20: =SUM(D8:D19) -> 0 | E20: 合計 | H20: =SUM(H8:H19) -> 125647.2 | I20: 合計 | L20: =SUM(L8:L19) -> 51897.6 | M20: 合計 | P20: =SUM(P8:P19) -> 49658.4 | Q20: 合計 | T20: =SUM(T8:T19) -> 30240 | U20: 合計 | X20: =SUM(X8:X19) -> 2772 | Y20: 合計 | AB20: =SUM(AB8:AB19) -> 61362 | AC20: 合計 | AF20: =SUM(AF8:AF19) -> 910.8

Sheet 泰安站
A1: 站別- | B1: 泰安 | E1: 站別- | F1: =$B$1 -> 泰安 | I1: 站別- | J1: =$B$1 -> 泰安 | M1: 站別- | N1: =$B$1 -> 泰安 | Q1: 站別- | R1: =$B$1 -> 泰安
A2: 年度別- | B2: ='卓蘭站'!B2 -> 115 | E2: 年度別- | F2: ='卓蘭站'!B2 -> 115 | I2: 年度別- | J2: ='卓蘭站'!B2 -> 115 | M2: 年度別- | N2: ='卓蘭站'!B2 -> 115 | Q2: 年度別- | R2: ='卓蘭站'!B2 -> 115
A3: 抽水井名稱- | B3: ='總表'!$C18 -> 新店圳一號抽水井 | E3: 抽水井名稱- | F3: ='總表'!$C19 -> 七公圳一號抽水井 | I3: 抽水井名稱- | J3: ='總表'!$C20 -> 七公圳二號抽水井 | M3: 抽水井名稱- | N3: ='總表'!C21 -> 新店圳二號抽水井 | Q3: 抽水井名稱- | R3: ='總表'!C22 -> 新店圳三號抽水井
A4: 水權狀號- | B4: ='總表'!$D18 -> B0130278 | E4: 水權狀號- | F4: ='總表'!$D19 -> B0130267 | I4: 水權狀號- | J4: ='總表'!$D20 -> B1040342 | M4: 水權狀號- | N4: ='總表'!D21 -> B1140020 | Q4: 水權狀號- | R4: ='總表'!D22 -> B1140033
A5: 核准年限- | B5: ='總表'!$E18 -> 1120201 | C5: ='總表'!$F18 -> 1170131 | E5: 核准年限- | F5: ='總表'!$E19 -> 1120201 | G5: ='總表'!$F19 -> 1170131 | I5: 核准年限- | J5: ='總表'!$E20 -> 1140624 | K5: ='總表'!$F20 -> 1190623 | M5: 核准年限- | N5: ='總表'!E21 -> 1140108 | O5: ='總表'!F21 -> 1190107 | Q5: 核准年限- | R5: ='總表'!E22 -> 1140120 | S5: ='總表'!F22 -> 1190119
A6: 備註- | B6: ='總表'!$K18 -> 20 | C6: 小時/日 | E6: 備註- | F6: ='總表'!$K19 -> 20 | G6: 小時/日 | I6: 備註- | J6: ='總表'!$K20 -> 8.15 | K6: 小時/日 | M6: 備註- | N6: ='總表'!K21 -> 4.6 | O6: 小時/日 | Q6: 備註- | R6: ='總表'!K22 -> 6.5 | S6: 小時/日
A7: 項目 月份 | B7: 抽水時間(hr) | C7: 水權引水量(cms) | D7: 抽水量(m³) | E7: 項目 月份 | F7: 抽水時間(hr) | G7: 水權引水量(cms) | H7: 抽水量(m³) | I7: 項目 月份 | J7: 抽水時間(hr) | K7: 水權引水量(cms) | L7: 抽水量(m³) | M7: 項目 月份 | N7: 抽水時間(hr) | O7: 水權引水量(cms) | P7: 抽水量(m³) | Q7: 項目 月份 | R7: 抽水時間(hr) | S7: 水權引水量(cms) | T7: 抽水量(m³)
A8: 1 | B8: 7 | C8: ='總表'!$J18 -> 0.076 | D8: =IF(B8="","",B8*C8*3600) -> 1915.2 | E8: 1 | F8: 29 | G8: ='總表'!$J19 -> 0.076 | H8: =IF(F8="","",F8*G8*3600) -> 7934.4 | I8: 1 | J8: 33 | K8: ='總表'!J20 -> 0.0482 | L8: =IF(J8="","",J8*K8*3600) -> 5726.16 | M8: 1 | N8: 0 | O8: ='總表'!J21 -> 0.032 | P8: =IF(N8="","",N8*O8*3600) -> 0 | Q8: 1 | R8: 0 | S8: ='總表'!J22 -> 0.028 | T8: =IF(R8="","",R8*S8*3600) -> 0
A9: 2 | B9: 76 | C9: =C8 -> 0.076 | D9: =IF(B9="","",B9*C9*3600) -> 20793.6 | E9: 2 | F9: 232 | G9: =G8 -> 0.076 | H9: =IF(F9="","",F9*G9*3600) -> 63475.2 | I9: 2 | J9: 232 | K9: =K8 -> 0.0482 | L9: =IF(J9="","",J9*K9*3600) -> 40256.64 | M9: 2 | N9: 30 | O9: =O8 -> 0.032 | P9: =IF(N9="","",N9*O9*3600) -> 3456 | Q9: 2 | R9: 30 | S9: =S8 -> 0.028 | T9: =IF(R9="","",R9*S9*3600) -> 3024
A10: 3 | B10: 744 | C10: =C8 -> 0.076 | D10: =IF(B10="","",B10*C10*3600) -> 203558.4 | E10: 3 | F10: 515 | G10: =G8 -> 0.076 | H10: =IF(F10="","",F10*G10*3600) -> 140904 | I10: 3 | J10: 686.5 | K10: =K8 -> 0.0482 | L10: =IF(J10="","",J10*K10*3600) -> 119121.48 | M10: 3 | N10: 591 | O10: =O8 -> 0.032 | P10: =IF(N10="","",N10*O10*3600) -> 68083.2 | Q10: 3 | R10: 591 | S10: =S8 -> 0.028 | T10: =IF(R10="","",R10*S10*3600) -> 59572.8
A11: 4 | B11: 265 | C11: =C8 -> 0.076 | D11: =IF(B11="","",B11*C11*3600) -> 72504 | E11: 4 | F11: 173 | G11: =G8 -> 0.076 | H11: =IF(F11="","",F11*G11*3600) -> 47332.8 | I11: 4 | J11: 229 | K11: =K8 -> 0.0482 | L11: =IF(J11="","",J11*K11*3600) -> 39736.08 | M11: 4 | N11: 265 | O11: =O8 -> 0.032 | P11: =IF(N11="","",N11*O11*3600) -> 30528 | Q11: 4 | R11: 265 | S11: =S8 -> 0.028 | T11: =IF(R11="","",R11*S11*3600) -> 26712
A12: 5 | B12: 414 | C12: =C8 -> 0.076 | D12: =IF(B12="","",B12*C12*3600) -> 113270.4 | E12: 5 | F12: 336 | G12: =G8 -> 0.076 | H12: =IF(F12="","",F12*G12*3600) -> 91929.6 | I12: 5 | J12: 336 | K12: =K8 -> 0.0482 | L12: =IF(J12="","",J12*K12*3600) -> 58302.72 | M12: 5 | N12: 361 | O12: =O8 -> 0.032 | P12: =IF(N12="","",N12*O12*3600) -> 41587.2 | Q12: 5 | R12: 361 | S12: =S8 -> 0.028 | T12: =IF(R12="","",R12*S12*3600) -> 36388.8
A13: 6 | B13: 14 | C13: =C8 -> 0.076 | D13: =IF(B13="","",B13*C13*3600) -> 3830.4 | E13: 6 | F13: 48 | G13: =G8 -> 0.076 | H13: =IF(F13="","",F13*G13*3600) -> 13132.8 | I13: 6 | J13: 48 | K13: =K8 -> 0.0482 | L13: =IF(J13="","",J13*K13*3600) -> 8328.96 | M13: 6 | N13: 115 | O13: =O8 -> 0.032 | P13: =IF(N13="","",N13*O13*3600) -> 13248 | Q13: 6 | R13: 115 | S13: =S8 -> 0.028 | T13: =IF(R13="","",R13*S13*3600) -> 11592
A14: 7 | B14: 0 | C14: =C8 -> 0.076 | D14: =IF(B14="","",B14*C14*3600) -> 0 | E14: 7 | F14: 0 | G14: =G8 -> 0.076 | H14: =IF(F14="","",F14*G14*3600) -> 0 | I14: 7 | J14: 0 | K14: =K8 -> 0.0482 | L14: =IF(J14="","",J14*K14*3600) -> 0 | M14: 7 | N14: 0 | O14: =O8 -> 0.032 | P14: =IF(N14="","",N14*O14*3600) -> 0 | Q14: 7 | R14: 0 | S14: =S8 -> 0.028 | T14: =IF(R14="","",R14*S14*3600) -> 0
A15: 8 | C15: =C8 -> 0.076 | D15: =IF(B15="","",B15*C15*3600) | E15: 8 | G15: =G8 -> 0.076 | H15: =IF(F15="","",F15*G15*3600) | I15: 8 | K15: =K8 -> 0.0482 | L15: =IF(J15="","",J15*K15*3600) | M15: 8 | O15: =O8 -> 0.032 | P15: =IF(N15="","",N15*O15*3600) | Q15: 8 | S15: =S8 -> 0.028 | T15: =IF(R15="","",R15*S15*3600)
A16: 9 | C16: =C8 -> 0.076 | D16: =IF(B16="","",B16*C16*3600) | E16: 9 | G16: =G8 -> 0.076 | H16: =IF(F16="","",F16*G16*3600) | I16: 9 | K16: =K8 -> 0.0482 | L16: =IF(J16="","",J16*K16*3600) | M16: 9 | O16: =O8 -> 0.032 | P16: =IF(N16="","",N16*O16*3600) | Q16: 9 | S16: =S8 -> 0.028 | T16: =IF(R16="","",R16*S16*3600)
A17: 10 | C17: =C8 -> 0.076 | D17: =IF(B17="","",B17*C17*3600) | E17: 10 | G17: =G8 -> 0.076 | H17: =IF(F17="","",F17*G17*3600) | I17: 10 | K17: =K8 -> 0.0482 | L17: =IF(J17="","",J17*K17*3600) | M17: 10 | O17: =O8 -> 0.032 | P17: =IF(N17="","",N17*O17*3600) | Q17: 10 | S17: =S8 -> 0.028 | T17: =IF(R17="","",R17*S17*3600)
A18: 11 | C18: =C8 -> 0.076 | D18: =IF(B18="","",B18*C18*3600) | E18: 11 | G18: =G8 -> 0.076 | H18: =IF(F18="","",F18*G18*3600) | I18: 11 | K18: =K8 -> 0.0482 | L18: =IF(J18="","",J18*K18*3600) | M18: 11 | O18: =O8 -> 0.032 | P18: =IF(N18="","",N18*O18*3600) | Q18: 11 | S18: =S8 -> 0.028 | T18: =IF(R18="","",R18*S18*3600)
A19: 12 | C19: =C8 -> 0.076 | D19: =IF(B19="","",B19*C19*3600) | E19: 12 | G19: =G8 -> 0.076 | H19: =IF(F19="","",F19*G19*3600) | I19: 12 | K19: =K8 -> 0.0482 | L19: =IF(J19="","",J19*K19*3600) | M19: 12 | O19: =O8 -> 0.032 | P19: =IF(N19="","",N19*O19*3600) | Q19: 12 | S19: =S8 -> 0.028 | T19: =IF(R19="","",R19*S19*3600)
A20: 合計 | D20: =SUM(D8:D19) -> 415872 | E20: 合計 | H20: =SUM(H8:H19) -> 364708.8 | I20: 合計 | L20: =SUM(L8:L19) -> 271472.04 | M20: 合計 | P20: =SUM(P8:P19) -> 156902.4 | Q20: 合計 | T20: =SUM(T8:T19) -> 137289.6

Sheet 屯子腳站
A1: 站別- | B1: 屯子腳 | E1: 站別- | F1: =$B$1 -> 屯子腳 | I1: 站別- | J1: =$B$1 -> 屯子腳 | M1: 站別- | N1: =$B$1 -> 屯子腳 | Q1: 站別- | R1: =$B$1 -> 屯子腳
A2: 年度別- | B2: ='卓蘭站'!B2 -> 115 | E2: 年度別- | F2: ='卓蘭站'!B2 -> 115 | I2: 年度別- | J2: ='卓蘭站'!B2 -> 115 | M2: 年度別- | N2: ='卓蘭站'!B2 -> 115 | Q2: 年度別- | R2: ='卓蘭站'!B2 -> 115
A3: 抽水井名稱- | B3: ='總表'!$C23 -> 內埔圳一號抽水井 | E3: 抽水井名稱- | F3: ='總表'!$C24 -> 內埔圳二號抽水井 | I3: 抽水井名稱- | J3: ='總表'!$C25 -> 內埔圳二支線一號抽水井 | M3: 抽水井名稱- | N3: ='總表'!$C26 -> 內埔圳二支線二號抽水井 | Q3: 抽水井名稱- | R3: ='總表'!$C27 -> 內埔圳梅仔腳溝支線水井
A4: 水權狀號- | B4: ='總表'!$D23 -> B0970028 | E4: 水權狀號- | F4: ='總表'!$D24 -> B0970027 | I4: 水權狀號- | J4: ='總表'!$D25 -> B1070014 | M4: 水權狀號- | N4: ='總表'!$D26 -> B1100760 | Q4: 水權狀號- | R4: ='總表'!$D27 -> B1140111
A5: 核准年限- | B5: ='總表'!$E23 -> 1120801 | C5: ='總表'!$F23 -> 1170731 | E5: 核准年限- | F5: ='總表'!$E24 -> 1120801 | G5: ='總表'!$F24 -> 1170731 | I5: 核准年限- | J5: ='總表'!$E25 -> 1120125 | K5: ='總表'!$F25 -> 1170124 | M5: 核准年限- | N5: ='總表'!$E26 -> 1101115 | O5: ='總表'!$F26 -> 1151114 | Q5: 核准年限- | R5: ='總表'!$E27 -> 1140513 | S5: ='總表'!$F27 -> 1190512
A6: 備註- | B6: ='總表'!$K23 -> 7 | C6: 小時/日 | E6: 備註- | F6: ='總表'!$K24 -> 10 | G6: 小時/日 | I6: 備註- | J6: ='總表'!$K25 -> 7 | K6: 小時/日 | M6: 備註- | N6: ='總表'!$K26 -> 12 | O6: 小時/日 | Q6: 備註- | R6: ='總表'!$K27 -> 4 | S6: 小時/日
A7: 項目 月份 | B7: 抽水時間(hr) | C7: 水權引水量(cms) | D7: 抽水量(m³) | E7: 項目 月份 | F7: 抽水時間(hr) | G7: 水權引水量(cms) | H7: 抽水量(m³) | I7: 項目 月份 | J7: 抽水時間(hr) | K7: 水權引水量(cms) | L7: 抽水量(m³) | M7: 項目 月份 | N7: 抽水時間(hr) | O7: 水權引水量(cms) | P7: 抽水量(m³) | Q7: 項目 月份 | R7: 抽水時間(hr) | S7: 水權引水量(cms) | T7: 抽水量(m³)
A8: 1 | B8: 0 | C8: ='總表'!$J23 -> 0.075 | D8: =IF(B8="","",B8*C8*3600) -> 0 | E8: 1 | F8: 0 | G8: ='總表'!$J24 -> 0.035 | H8: =IF(F8="","",F8*G8*3600) -> 0 | I8: 1 | J8: 0 | K8: ='總表'!$J25 -> 0.0286 | L8: =IF(J8="","",J8*K8*3600) -> 0 | M8: 1 | N8: 0 | O8: ='總表'!$J26 -> 0.039 | P8: =IF(N8="","",N8*O8*3600) -> 0 | Q8: 1 | R8: 0 | S8: ='總表'!$J27 -> 0.07 | T8: =IF(R8="","",R8*S8*3600) -> 0
A9: 2 | B9: 0 | C9: =C8 -> 0.075 | D9: =IF(B9="","",B9*C9*3600) -> 0 | E9: 2 | F9: 0 | G9: =G8 -> 0.035 | H9: =IF(F9="","",F9*G9*3600) -> 0 | I9: 2 | J9: 0 | K9: =K8 -> 0.0286 | L9: =IF(J9="","",J9*K9*3600) -> 0 | M9: 2 | N9: 0 | O9: =O8 -> 0.039 | P9: =IF(N9="","",N9*O9*3600) -> 0 | Q9: 2 | R9: 0 | S9: =S8 -> 0.07 | T9: =IF(R9="","",R9*S9*3600) -> 0
A10: 3 | B10: 47.5 | C10: =C8 -> 0.075 | D10: =IF(B10="","",B10*C10*3600) -> 12825 | E10: 3 | F10: 80.5 | G10: =G8 -> 0.035 | H10: =IF(F10="","",F10*G10*3600) -> 10143 | I10: 3 | J10: 61 | K10: =K8 -> 0.0286 | L10: =IF(J10="","",J10*K10*3600) -> 6280.56 | M10: 3 | N10: 101 | O10: =O8 -> 0.039 | P10: =IF(N10="","",N10*O10*3600) -> 14180.4 | Q10: 3 | R10: 21 | S10: =S8 -> 0.07 | T10: =IF(R10="","",R10*S10*3600) -> 5292
A11: 4 | B11: 62 | C11: =C8 -> 0.075 | D11: =IF(B11="","",B11*C11*3600) -> 16740 | E11: 4 | F11: 32 | G11: =G8 -> 0.035 | H11: =IF(F11="","",F11*G11*3600) -> 4032 | I11: 4 | J11: 78 | K11: =K8 -> 0.0286 | L11: =IF(J11="","",J11*K11*3600) -> 8030.88 | M11: 4 | N11: 101 | O11: =O8 -> 0.039 | P11: =IF(N11="","",N11*O11*3600) -> 14180.4 | Q11: 4 | R11: 50 | S11: =S8 -> 0.07 | T11: =IF(R11="","",R11*S11*3600) -> 12600
A12: 5 | B12: 0 | C12: =C8 -> 0.075 | D12: =IF(B12="","",B12*C12*3600) -> 0 | E12: 5 | F12: 24 | G12: =G8 -> 0.035 | H12: =IF(F12="","",F12*G12*3600) -> 3024 | I12: 5 | J12: 51.5 | K12: =K8 -> 0.0286 | L12: =IF(J12="","",J12*K12*3600) -> 5302.44 | M12: 5 | N12: 67 | O12: =O8 -> 0.039 | P12: =IF(N12="","",N12*O12*3600) -> 9406.8 | Q12: 5 | R12: 43.5 | S12: =S8 -> 0.07 | T12: =IF(R12="","",R12*S12*3600) -> 10962
A13: 6 | B13: 0 | C13: =C8 -> 0.075 | D13: =IF(B13="","",B13*C13*3600) -> 0 | E13: 6 | F13: 0 | G13: =G8 -> 0.035 | H13: =IF(F13="","",F13*G13*3600) -> 0 | I13: 6 | J13: 44 | K13: =K8 -> 0.0286 | L13: =IF(J13="","",J13*K13*3600) -> 4530.24 | M13: 6 | N13: 44 | O13: =O8 -> 0.039 | P13: =IF(N13="","",N13*O13*3600) -> 6177.6 | Q13: 6 | R13: 18.5 | S13: =S8 -> 0.07 | T13: =IF(R13="","",R13*S13*3600) -> 4662
A14: 7 | B14: 0 | C14: =C8 -> 0.075 | D14: =IF(B14="","",B14*C14*3600) -> 0 | E14: 7 | F14: 0 | G14: =G8 -> 0.035 | H14: =IF(F14="","",F14*G14*3600) -> 0 | I14: 7 | J14: 0 | K14: =K8 -> 0.0286 | L14: =IF(J14="","",J14*K14*3600) -> 0 | M14: 7 | N14: 13 | O14: =O8 -> 0.039 | P14: =IF(N14="","",N14*O14*3600) -> 1825.2 | Q14: 7 | R14: 0 | S14: =S8 -> 0.07 | T14: =IF(R14="","",R14*S14*3600) -> 0
A15: 8 | C15: =C8 -> 0.075 | D15: =IF(B15="","",B15*C15*3600) | E15: 8 | G15: =G8 -> 0.035 | H15: =IF(F15="","",F15*G15*3600) | I15: 8 | K15: =K8 -> 0.0286 | L15: =IF(J15="","",J15*K15*3600) | M15: 8 | O15: =O8 -> 0.039 | P15: =IF(N15="","",N15*O15*3600) | Q15: 8 | S15: =S8 -> 0.07 | T15: =IF(R15="","",R15*S15*3600)
A16: 9 | C16: =C8 -> 0.075 | D16: =IF(B16="","",B16*C16*3600) | E16: 9 | G16: =G8 -> 0.035 | H16: =IF(F16="","",F16*G16*3600) | I16: 9 | K16: =K8 -> 0.0286 | L16: =IF(J16="","",J16*K16*3600) | M16: 9 | O16: =O8 -> 0.039 | P16: =IF(N16="","",N16*O16*3600) | Q16: 9 | S16: =S8 -> 0.07 | T16: =IF(R16="","",R16*S16*3600)
A17: 10 | C17: =C8 -> 0.075 | D17: =IF(B17="","",B17*C17*3600) | E17: 10 | G17: =G8 -> 0.035 | H17: =IF(F17="","",F17*G17*3600) | I17: 10 | K17: =K8 -> 0.0286 | L17: =IF(J17="","",J17*K17*3600) | M17: 10 | O17: =O8 -> 0.039 | P17: =IF(N17="","",N17*O17*3600) | Q17: 10 | S17: =S8 -> 0.07 | T17: =IF(R17="","",R17*S17*3600)
A18: 11 | C18: =C8 -> 0.075 | D18: =IF(B18="","",B18*C18*3600) | E18: 11 | G18: =G8 -> 0.035 | H18: =IF(F18="","",F18*G18*3600) | I18: 11 | K18: =K8 -> 0.0286 | L18: =IF(J18="","",J18*K18*3600) | M18: 11 | O18: =O8 -> 0.039 | P18: =IF(N18="","",N18*O18*3600) | Q18: 11 | S18: =S8 -> 0.07 | T18: =IF(R18="","",R18*S18*3600)
A19: 12 | C19: =C8 -> 0.075 | D19: =IF(B19="","",B19*C19*3600) | E19: 12 | G19: =G8 -> 0.035 | H19: =IF(F19="","",F19*G19*3600) | I19: 12 | K19: =K8 -> 0.0286 | L19: =IF(J19="","",J19*K19*3600) | M19: 12 | O19: =O8 -> 0.039 | P19: =IF(N19="","",N19*O19*3600) | Q19: 12 | S19: =S8 -> 0.07 | T19: =IF(R19="","",R19*S19*3600)
A20: 合計 | D20: =SUM(D8:D19) -> 29565 | E20: 合計 | H20: =SUM(H8:H19) -> 17199 | I20: 合計 | L20: =SUM(L8:L19) -> 24144.12 | M20: 合計 | P20: =SUM(P8:P19) -> 45770.4 | Q20: 合計 | T20: =SUM(T8:T19) -> 33516

Sheet 月眉站
A1: 站別- | B1: 月眉 | E1: 站別- | F1: =$B$1 -> 月眉 | I1: 站別- | J1: =$B$1 -> 月眉 | M1: 站別- | N1: =$B$1 -> 月眉 | Q1: 站別- | R1: =$B$1 -> 月眉 | U1: 站別- | V1: =$B$1 -> 月眉 | Y1: 站別- | Z1: =$B$1 -> 月眉 | AC1: 站別- | AD1: =$B$1 -> 月眉 | AG1: 站別- | AH1: =$B$1 -> 月眉 | AK1: 站別- | AL1: =$B$1 -> 月眉 | AO1: 站別- | AP1: =$B$1 -> 月眉 | AS1: 站別- | AT1: =$B$1 -> 月眉 | AW1: 站別- | AX1: =$B$1 -> 月眉 | BA1: 站別- | BB1: =$B$1 -> 月眉 | BE1: 站別- | BF1: =$B$1 -> 月眉 | BI1: 站別- | BJ1: =$B$1 -> 月眉 | BM1: 站別- | BN1: =$B$1 -> 月眉
A2: 年度別- | B2: ='卓蘭站'!B2 -> 115 | E2: 年度別- | F2: ='卓蘭站'!B2 -> 115 | I2: 年度別- | J2: ='卓蘭站'!B2 -> 115 | M2: 年度別- | N2: ='卓蘭站'!B2 -> 115 | Q2: 年度別- | R2: ='卓蘭站'!B2 -> 115 | U2: 年度別- | V2: ='卓蘭站'!B2 -> 115 | Y2: 年度別- | Z2: ='卓蘭站'!B2 -> 115 | AC2: 年度別- | AD2: ='卓蘭站'!B2 -> 115 | AG2: 年度別- | AH2: ='卓蘭站'!B2 -> 115 | AK2: 年度別- | AL2: ='卓蘭站'!B2 -> 115 | AO2: 年度別- | AP2: ='卓蘭站'!B2 -> 115 | AS2: 年度別- | AT2: ='卓蘭站'!B2 -> 115 | AW2: 年度別- | AX2: ='卓蘭站'!B2 -> 115 | BA2: 年度別- | BB2: ='卓蘭站'!B2 -> 115 | BE2: 年度別- | BF2: ='卓蘭站'!B2 -> 115 | BI2: 年度別- | BJ2: ='卓蘭站'!B2 -> 115 | BM2: 年度別- | BN2: ='卓蘭站'!B2 -> 115
A3: 抽水井名稱- | B3: ='總表'!$C36 -> 后里圳幹線抽水井 | E3: 抽水井名稱- | F3: ='總表'!$C37 -> 月眉站舊辦公廳地下水抽水井 | I3: 抽水井名稱- | J3: ='總表'!$C38 -> 后里圳月眉排水補給抽水井 | M3: 抽水井名稱- | N3: ='總表'!$C39 -> 后里圳三支線上游補給抽水井 | Q3: 抽水井名稱- | R3: ='總表'!$C40 -> 后里圳三支線中游補給抽水井 | U3: 抽水井名稱- | V3: ='總表'!$C41 -> 后里圳三支線中游二號抽水井 | Y3: 抽水井名稱- | Z3: ='總表'!$C42 -> 后里圳三支線下游補給抽水井 | AC3: 抽水井名稱- | AD3: ='總表'!$C43 -> 后里圳三支線下游二號抽水井 | AG3: 抽水井名稱- | AH3: ='總表'!$C44 -> 后里圳四支線中下游抽水井 | AK3: 抽水井名稱- | AL3: ='總表'!$C45 -> 后里圳五支線補給抽水井 | AO3: 抽水井名稱- | AP3: ='總表'!$C46 -> 后里圳五支線中下游抽水井 | AS3: 抽水井名稱- | AT3: ='總表'!$C47 -> 后里圳五支線下游抽水井 | AW3: 抽水井名稱- | AX3: ='總表'!$C48 -> 后里圳五支線之一上游補給抽水井 | BA3: 抽水井名稱- | BB3: ='總表'!$C49 -> 后里圳五支線之一下游補給抽水井 | BE3: 抽水井名稱- | BF3: ='總表'!$C50 -> 后里圳五支線之一延長線補給抽水井 | BI3: 抽水井名稱- | BJ3: ='總表'!$C51 -> 后里圳五支線之一延長線上游抽水井 | BM3: 抽水井名稱- | BN3: ='總表'!$C52 -> 后里圳五支線之一延長線下游抽水井
